Workbook

Sheet 01_FASTPPH
B2: COPY REPORT GENERATED BY FASTPPH
A8: ID | B8: DDP | C8: elementid | D8: Component Name | E8: elem 1 id | F8: elem 1 Node id | G8: elem 2 id | H8: elem 2 Node id | I8: box dimension | J8: loadcase | K8: file Name | L8: LoadCase Name | M8: Time Step Name | N8: pierced location | O8: Fx | P8: Fy | Q8: Fz | R8: MaxFz | S8: p1 | T8: p2 | U8: p3 | V8: p4 | W8: p5 | X8: p6 | Y8: p7 | Z8: p8 | AA8: p9 | AB8: p10 | AC8: p11 | AD8: p12 | AE8: p13 | AF8: p14 | AG8: p15 | AH8: p16 | AI8: p17 | AJ8: p18 | AK8: p19 | AL8: p20 | AM8: Fxx p1 | AN8: Fxx p2 | AO8: Fxx p3 | AP8: Fxx p4 | AQ8: Fxx p5 | AR8: Fxx p6 | AS8: Fxx p7 | AT8: Fxx p8 | AU8: Fxx p9 | AV8: Fxx p10 | AW8: Fxx p11 | AX8: Fxx p12 | AY8: Fxx p13 | AZ8: Fxx p14 | BA8: Fxx p15 | BB8: Fxx p16 | BC8: Fxx p17 | BD8: Fxx p18 | BE8: Fxx p19 | BF8: Fxx p20 | BG8: Fyy p1 | BH8: Fyy p2 | BI8: Fyy p3 | BJ8: Fyy p4 | BK8: Fyy p5 | BL8: Fyy p6 | BM8: Fyy p7 | BN8: Fyy p8 | BO8: Fyy p9 | BP8: Fyy p10 | BQ8: Fyy p11 | BR8: Fyy p12 | BS8: Fyy p13 | BT8: Fyy p14 | BU8: Fyy p15 | BV8: Fyy p16 | BW8: Fyy p17 | BX8: Fyy p18 | BY8: Fyy p19 | BZ8: Fyy p20 | CA8: Fxy p1 | CB8: Fxy p2 | CC8: Fxy p3 | CD8: Fxy p4 | CE8: Fxy p5 | CF8: Fxy p6 | CG8: Fxy p7 | CH8: Fxy p8 | CI8: Fxy p9 | CJ8: Fxy p10 | CK8: Fxy p11 | CL8: Fxy p12 | CM8: Fxy p13 | CN8: Fxy p14 | CO8: Fxy p15 | CP8: Fxy p16 | CQ8: Fxy p17 | CR8: Fxy p18 | CS8: Fxy p19 | CT8: Fxy p20 | CU8: Mxx p1 | CV8: Mxx p2 | CW8: Mxx p3 | CX8: Mxx p4 | CY8: Mxx p5 | CZ8: Mxx p6 | DA8: Mxx p7 | DB8: Mxx p8 | DC8: Mxx p9 | DD8: Mxx p10 | DE8: Mxx p11 | DF8: Mxx p12 | DG8: Mxx p13 | DH8: Mxx p14 | DI8: Mxx p15 | DJ8: Mxx p16 | DK8: Mxx p17 | DL8: Mxx p18 | DM8: Mxx p19 | DN8: Mxx p20 | DO8: Myy p1 | DP8: Myy p2 | DQ8: Myy p3 | DR8: Myy p4 | DS8: Myy p5 | DT8: Myy p6 | DU8: Myy p7 | DV8: Myy p8 | DW8: Myy p9 | DX8: Myy p10 | DY8: Myy p11 | DZ8: Myy p12 | EA8: Myy p13 | EB8: Myy p14 | EC8: Myy p15 | ED8: Myy p16 | EE8: Myy p17 | EF8: Myy p18 | EG8: Myy p19 | EH8: Myy p20 | EI8: Mxy p1 | EJ8: Mxy p2 | EK8: Mxy p3 | EL8: Mxy p4 | EM8: Mxy p5 | EN8: Mxy p6 | EO8: Mxy p7 | EP8: Mxy p8 | EQ8: Mxy p9 | ER8: Mxy p10 | ES8: Mxy p11 | ET8: Mxy p12 | EU8: Mxy p13 | EV8: Mxy p14 | EW8: Mxy p15 | EX8: Mxy p16 | EY8: Mxy p17 | EZ8: Mxy p18 | FA8: Mxy p19 | FB8: Mxy p20 | FC8: Nx bypass | FD8: Nx total | FE8: Ny bypass | FF8: Ny total | FG8: Nxy bypass | FH8: Nxy total | FI8: Mx total | FJ8: My total | FK8: Mxy total | FL8: DLS Ratio | FM8: Remark
A9: 1 | B9: 1 | C9: 2501542 | D9: SpliceOutbRH | E9: 2908020 | F9: 2908020 | G9: 0 | H9: 0 | I9: 51.48 | J9: 2_101_0 | K9: CDR_Pivot_V161_rightdown_all | L9: SUBCASE 101 = STLN ULT (INTACT) :STLN ULT (INTACT) | M9: Simulation 1 | N9: 28859.525904303933 171.7761413261218 4078.5102502192385 | O9: 6849.65 | P9: -6123.35 | Q9: 487.669 | R9: 8901.54 | S9: 28823.728019846505 173.045528096482 4084.990630269816 | T9: 28832.174954996284 172.53777338833794 4090.8557038185277 | U9: 28840.621890146063 172.03001868019385 4096.72077736724 | V9: 28849.06882529584 171.52226397204976 4102.585850915952 | W9: 28857.515760445618 171.01450926390567 4108.450924464663 | X9: 28865.962695595397 170.5067545557616 4114.315998013376 | Y9: 28871.83491422859 170.5067545557616 4105.858772444433 | Z9: 28877.707132861782 170.5067545557616 4097.40154687549 | AA9: 28883.579351494976 170.5067545557616 4088.944321306547 | AB9: 28889.451570128167 170.5067545557616 4080.487095737604 | AC9: 28895.32378876136 170.5067545557616 4072.0298701686606 | AD9: 28886.876853611582 171.01450926390567 4066.164796619949 | AE9: 28878.429918461803 171.52226397204976 4060.2997230712367 | AF9: 28869.982983312027 172.03001868019385 4054.434649522525 | AG9: 28861.53604816225 172.53777338833794 4048.569575973813 | AH9: 28853.08911301247 173.045528096482 4042.704502425101 | AI9: 28847.216894379275 173.045528096482 4051.161727994044 | AJ9: 28841.344675746084 173.045528096482 4059.6189535629874 | AK9: 28835.47245711289 173.045528096482 4068.07617913193 | AL9: 28829.6002384797 173.045528096482 4076.5334047008732 | AM9: 0 | AN9: 0 | AO9: 0 | AP9: 0 | AQ9: 0 | AR9: 0 | AS9: 0 | AT9: 0 | AU9: 0 | AV9: 0 | AW9: 0 | AX9: 0 | AY9: 0 | AZ9: 0 | BA9: 0 | BB9: 0 | BC9: 0 | BD9: 0 | BE9: 0 | BF9: 0 | BG9: 0 | BH9: 0 | BI9: 0 | BJ9: 0 | BK9: 0 | BL9: 0 | BM9: 0 | BN9: 0 | BO9: 0 | BP9: 0 | BQ9: 0 | BR9: 0 | BS9: 0 | BT9: 0 | BU9: 0 | BV9: 0 | BW9: 0 | BX9: 0 | BY9: 0 | BZ9: 0 | CA9: 0 | CB9: 0 | CC9: 0 | CD9: 0 | CE9: 0 | CF9: 0 | CG9: 0 | CH9: 0 | CI9: 0 | CJ9: 0 | CK9: 0 | CL9: 0 | CM9: 0 | CN9: 0 | CO9: 0 | CP9: 0 | CQ9: 0 | CR9: 0 | CS9: 0 | CT9: 0 | CU9: 0 | CV9: 0 | CW9: 0 | CX9: 0 | CY9: 0 | CZ9: 0 | DA9: 0 | DB9: 0 | DC9: 0 | DD9: 0 | DE9: 0 | DF9: 0 | DG9: 0 | DH9: 0 | DI9: 0 | DJ9: 0 | DK9: 0 | DL9: 0 | DM9: 0 | DN9: 0 | DO9: 0 | DP9: 0 | DQ9: 0 | DR9: 0 | DS9: 0 | DT9: 0 | DU9: 0 | DV9: 0 | DW9: 0 | DX9: 0 | DY9: 0 | DZ9: 0 | EA9: 0 | EB9: 0 | EC9: 0 | ED9: 0 | EE9: 0 | EF9: 0 | EG9: 0 | EH9: 0 | EI9: 0 | EJ9: 0 | EK9: 0 | EL9: 0 | EM9: 0 | EN9: 0 | EO9: 0 | EP9: 0 | EQ9: 0 | ER9: 0 | ES9: 0 | ET9: 0 | EU9: 0 | EV9: 0 | EW9: 0 | EX9: 0 | EY9: 0 | EZ9: 0 | FA9: 0 | FB9: 0 | FC9: 0 | FD9: 0 | FE9: 0 | FF9: 0 | FG9: 0 | FH9: 0 | FI9: 0 | FJ9: 0 | FK9: 0 | FL9: 0
A10: 2 | B10: 1 | C10: 2501542 | D10: SpliceOutbRH | E10: 2908020 | F10: 2908020 | G10: 0 | H10: 0 | I10: 51.48 | J10: 3_102_0 | K10: CDR_Pivot_V161_leftdown_all | L10: SUBCASE 102 = STLP ULT (INTACT) :STLP ULT (INTACT) | M10: Simulation 1 | N10: 28859.525904303933 171.7761413261218 4078.5102502192385 | O10: -7074 | P10: 6791.27 | Q10: -601.103 | R10: 0 | S10: 28823.728019846505 173.045528096482 4084.990630269816 | T10: 28832.174954996284 172.53777338833794 4090.8557038185277 | U10: 28840.621890146063 172.03001868019385 4096.72077736724 | V10: 28849.06882529584 171.52226397204976 4102.585850915952 | W10: 28857.515760445618 171.01450926390567 4108.450924464663 | X10: 28865.962695595397 170.5067545557616 4114.315998013376 | Y10: 28871.83491422859 170.5067545557616 4105.858772444433 | Z10: 28877.707132861782 170.5067545557616 4097.40154687549 | AA10: 28883.579351494976 170.5067545557616 4088.944321306547 | AB10: 28889.451570128167 170.5067545557616 4080.487095737604 | AC10: 28895.32378876136 170.5067545557616 4072.0298701686606 | AD10: 28886.876853611582 171.01450926390567 4066.164796619949 | AE10: 28878.429918461803 171.52226397204976 4060.2997230712367 | AF10: 28869.982983312027 172.03001868019385 4054.434649522525 | AG10: 28861.53604816225 172.53777338833794 4048.569575973813 | AH10: 28853.08911301247 173.045528096482 4042.704502425101 | AI10: 28847.216894379275 173.045528096482 4051.161727994044 | AJ10: 28841.344675746084 173.045528096482 4059.6189535629874 | AK10: 28835.47245711289 173.045528096482 4068.07617913193 | AL10: 28829.6002384797 173.045528096482 4076.5334047008732 | AM10: 0 | AN10: 0 | AO10: 0 | AP10: 0 | AQ10: 0 | AR10: 0 | AS10: 0 | AT10: 0 | AU10: 0 | AV10: 0 | AW10: 0 | AX10: 0 | AY10: 0 | AZ10: 0 | BA10: 0 | BB10: 0 | BC10: 0 | BD10: 0 | BE10: 0 | BF10: 0 | BG10: 0 | BH10: 0 | BI10: 0 | BJ10: 0 | BK10: 0 | BL10: 0 | BM10: 0 | BN10: 0 | BO10: 0 | BP10: 0 | BQ10: 0 | BR10: 0 | BS10: 0 | BT10: 0 | BU10: 0 | BV10: 0 | BW10: 0 | BX10: 0 | BY10: 0 | BZ10: 0 | CA10: 0 | CB10: 0 | CC10: 0 | CD10: 0 | CE10: 0 | CF10: 0 | CG10: 0 | CH10: 0 | CI10: 0 | CJ10: 0 | CK10: 0 | CL10: 0 | CM10: 0 | CN10: 0 | CO10: 0 | CP10: 0 | CQ10: 0 | CR10: 0 | CS10: 0 | CT10: 0 | CU10: 0 | CV10: 0 | CW10: 0 | CX10: 0 | CY10: 0 | CZ10: 0 | DA10: 0 | DB10: 0 | DC10: 0 | DD10: 0 | DE10: 0 | DF10: 0 | DG10: 0 | DH10: 0 | DI10: 0 | DJ10: 0 | DK10: 0 | DL10: 0 | DM10: 0 | DN10: 0 | DO10: 0 | DP10: 0 | DQ10: 0 | DR10: 0 | DS10: 0 | DT10: 0 | DU10: 0 | DV10: 0 | DW10: 0 | DX10: 0 | DY10: 0 | DZ10: 0 | EA10: 0 | EB10: 0 | EC10: 0 | ED10: 0 | EE10: 0 | EF10: 0 | EG10: 0 | EH10: 0 | EI10: 0 | EJ10: 0 | EK10: 0 | EL10: 0 | EM10: 0 | EN10: 0 | EO10: 0 | EP10: 0 | EQ10: 0 | ER10: 0 | ES10: 0 | ET10: 0 | EU10: 0 | EV10: 0 | EW10: 0 | EX10: 0 | EY10: 0 | EZ10: 0 | FA10: 0 | FB10: 0 | FC10: 0 | FD10: 0 | FE10: 0 | FF10: 0 | FG10: 0 | FH10: 0 | FI10: 0 | FJ10: 0 | FK10: 0 | FL10: 0
A11: 3 | B11: 1 | C11: 1500994 | D11: SkinRH | E11: 2908020 | F11: 1908022 | G11: 3908020 | H11: 1908023 | I11: 57.915 | J11: 2_101_0 | K11: CDR_Pivot_V161_rightdown_all | L11: SUBCASE 101 = STLN ULT (INTACT) :STLN ULT (INTACT) | M11: Simulation 1 | N11: 28859.525904303933 161.59140378988127 4078.5102502192385 | O11: 917.802 | P11: -3276.95 | Q11: 757.354 | R11: 8901.54 | S11: 28818.64423300476 163.35019707006083 4076.8764783612655 | T11: 28826.47870437506 162.646679757989 4085.3789492221144 | U11: 28834.31317574536 161.94316244591718 4093.881420082963 | V11: 28842.147647115657 161.23964513384536 4102.383890943812 | W11: 28849.982118485957 160.53612782177353 4110.886361804661 | X11: 28857.816589856255 159.8326105097017 4119.388832665509 | Y11: 28866.334787005624 159.8326105097017 4111.539870547849 | Z11: 28874.852984154993 159.8326105097017 4103.69090843019 | AA11: 28883.371181304366 159.8326105097017 4095.8419463125306 | AB11: 28891.889378453736 159.8326105097017 4087.992984194871 | AC11: 28900.407575603105 159.8326105097017 4080.1440220772115 | AD11: 28892.573104232808 160.53612782177353 4071.6415512163626 | AE11: 28884.738632862507 161.23964513384536 4063.139080355514 | AF11: 28876.90416149221 161.94316244591718 4054.636609494665 | AG11: 28869.06969012191 162.646679757989 4046.1341386338167 | AH11: 28861.23521875161 163.35019707006083 4037.631667772968 | AI11: 28852.717021602242 163.35019707006083 4045.4806298906274 | AJ11: 28844.198824452873 163.35019707006083 4053.329592008287 | AK11: 28835.6806273035 163.35019707006083 4061.1785541259464 | AL11: 28827.16243015413 163.35019707006083 4069.027516243606 | AM11: 192.524 | AN11: 225.421 | AO11: 250.962 | AP11: 278.275 | AQ11: 303.974 | AR11: 328.534 | AS11: 182.085 | AT11: 21.268 | AU11: -133.79 | AV11: -245.003 | AW11: -346.73 | AX11: -406.513 | AY11: -440.298 | AZ11: -473.07 | BA11: -504.042 | BB11: -528.948 | BC11: -373.125 | BD11: -225.255 | BE11: -83.1735 | BF11: 52.0778 | BG11: 393.466 | BH11: 395.354 | BI11: 396.26 | BJ11: 391.561 | BK11: 383.287 | BL11: 375.24 | BM11: 364.651 | BN11: 351.466 | BO11: 336.484 | BP11: 307.866 | BQ11: 293.659 | BR11: 284.34 | BS11: 272.364 | BT11: 270.789 | BU11: 275.08 | BV11: 279.5 | BW11: 297.796 | BX11: 321.103 | BY11: 343.895 | BZ11: 370.607 | CA11: -554.874 | CB11: -568.036 | CC11: -571.565 | CD11: -572.387 | CE11: -579.112 | CF11: -588.89 | CG11: -563.336 | CH11: -542.209 | CI11: -517.771 | CJ11: -483.796 | CK11: -448.571 | CL11: -450.443 | CM11: -443.398 | CN11: -438.094 | CO11: -428.981 | CP11: -415.144 | CQ11: -435.746 | CR11: -457.191 | CS11: -485.62 | CT11: -518.81 | CU11: -4738.23 | CV11: -5363.76 | CW11: -5788.31 | CX11: -6177.03 | CY11: -6607.87 | CZ11: -7207.21 | DA11: -7808.71 | DB11: -8473.79 | DC11: -9607.54 | DD11: -10685.6 | DE11: -12253.7 | DF11: -10629 | DG11: -9509.28 | DH11: -8541.08 | DI11: -7484.77 | DJ11: -6244.74 | DK11: -6167.95 | DL11: -5921.69 | DM11: -5705.32 | DN11: -5284.84 | DO11: -1656.86 | DP11: -1719.06 | DQ11: -1798.34 | DR11: -1917.61 | DS11: -2104.68 | DT11: -2350.44 | DU11: -2009.23 | DV11: -1706.17 | DW11: -1877.25 | DX11: -2901.87 | DY11: -4689.41 | DZ11: -4078.52 | EA11: -3588.49 | EB11: -3214.9 | EC11: -2929.98 | ED11: -2625.36 | EE11: -2869.82 | EF11: -3039.03 | EG11: -2742.23 | EH11: -2177.75 | EI11: 467.691 | EJ11: 749.814 | EK11: 1018.67 | EL11: 1227.66 | EM11: 1426.9 | EN11: 1684.72 | EO11: 1738.16 | EP11: 1687.67 | EQ11: 1473.88 | ER11: 743.097 | ES11: 599.067 | ET11: 320.631 | EU11: 125.509 | EV11: 17.2275 | EW11: -21.8539 | EX11: -69.8873 | EY11: -53.3397 | EZ11: 24.6894 | FA11: 130.183 | FB11: 297.217 | FC11: -32.2725 | FD11: -160.983 | FE11: 279.289 | FF11: 389.195 | FG11: -437.439 | FH11: -572.477 | FI11: 7508.27 | FJ11: 2722.8 | FK11: -677.887 | FL11: 0.365124
A12: 4 | B12: 1 | C12: 1500994 | D12: SkinRH | E12: 2908020 | F12: 1908022 | G12: 3908020 | H12: 1908023 | I12: 57.915 | J12: 3_102_0 | K12: CDR_Pivot_V161_leftdown_all | L12: SUBCASE 102 = STLP ULT (INTACT) :STLP ULT (INTACT) | M12: Simulation 1 | N12: 28859.525904303933 161.59140378988127 4078.5102502192385 | O12: -717.404 | P12: 3469.09 | Q12: -952.383 | R12: 0 | S12: 28818.64423300476 163.35019707006083 4076.8764783612655 | T12: 28826.47870437506 162.646679757989 4085.3789492221144 | U12: 28834.31317574536 161.94316244591718 4093.881420082963 | V12: 28842.147647115657 161.23964513384536 4102.383890943812 | W12: 28849.982118485957 160.53612782177353 4110.886361804661 | X12: 28857.816589856255 159.8326105097017 4119.388832665509 | Y12: 28866.334787005624 159.8326105097017 4111.539870547849 | Z12: 28874.852984154993 159.8326105097017 4103.69090843019 | AA12: 28883.371181304366 159.8326105097017 4095.8419463125306 | AB12: 28891.889378453736 159.8326105097017 4087.992984194871 | AC12: 28900.407575603105 159.8326105097017 4080.1440220772115 | AD12: 28892.573104232808 160.53612782177353 4071.6415512163626 | AE12: 28884.738632862507 161.23964513384536 4063.139080355514 | AF12: 28876.90416149221 161.94316244591718 4054.636609494665 | AG12: 28869.06969012191 162.646679757989 4046.1341386338167 | AH12: 28861.23521875161 163.35019707006083 4037.631667772968 | AI12: 28852.717021602242 163.35019707006083 4045.4806298906274 | AJ12: 28844.198824452873 163.35019707006083 4053.329592008287 | AK12: 28835.6806273035 163.35019707006083 4061.1785541259464 | AL12: 28827.16243015413 163.35019707006083 4069.027516243606 | AM12: -116.451 | AN12: -148.799 | AO12: -179.254 | AP12: -215.144 | AQ12: -257.743 | AR12: -304.255 | AS12: -44.2298 | AT12: 247.161 | AU12: 533.201 | AV12: 745.877 | AW12: 966.418 | AX12: 955.151 | AY12: 909.387 | AZ12: 869.916 | BA12: 838.855 | BB12: 810.925 | BC12: 635.458 | BD12: 451.052 | BE12: 262.24 | BF12: 75.1013 | BG12: -406.209 | BH12: -404.797 | BI12: -399.816 | BJ12: -387.103 | BK12: -366.31 | BL12: -343.177 | BM12: -354.702 | BN12: -372.016 | BO12: -392.92 | BP12: -396.615 | BQ12: -416.15 | BR12: -405.649 | BS12: -384.515 | BT12: -371.209 | BU12: -363.495 | BV12: -356.052 | BW12: -368.187 | BX12: -380.033 | BY12: -388.059 | BZ12: -398.718 | CA12: 479.038 | CB12: 477.876 | CC12: 463.934 | CD12: 447.47 | CE12: 435.102 | CF12: 428.168 | CG12: 381.892 | CH12: 360.559 | CI12: 365.186 | CJ12: 387.531 | CK12: 429.119 | CL12: 456.124 | CM12: 468.303 | CN12: 477.177 | CO12: 476.99 | CP12: 468.23 | CQ12: 442.633 | CR12: 428.508 | CS12: 431.5 | CT12: 449.206 | CU12: 5388.29 | CV12: 6160.73 | CW12: 6733.86 | CX12: 7289.31 | CY12: 7933.8 | CZ12: 8783.44 | DA12: 9405.33 | DB12: 10045.9 | DC12: 11059.1 | DD12: 11953.9 | DE12: 13397.2 | DF12: 11693.9 | DG12: 10429.2 | DH12: 9310.48 | DI12: 8107.33 | DJ12: 6735.38 | DK12: 6739.84 | DL12: 6537.27 | DM12: 6346.14 | DN12: 5932.99 | DO12: 1982.62 | DP12: 2068.54 | DQ12: 2169.46 | DR12: 2306.06 | DS12: 2497.28 | DT12: 2730.4 | DU12: 2426.62 | DV12: 2199.05 | DW12: 2455.29 | DX12: 3494.94 | DY12: 5355.14 | DZ12: 4776.96 | EA12: 4259.24 | EB12: 3836.42 | EC12: 3494 | ED12: 3127.87 | EE12: 3388.81 | EF12: 3545.8 | EG12: 3205.4 | EH12: 2574.53 | EI12: -307.596 | EJ12: -579.425 | EK12: -842.722 | EL12: -1050.39 | EM12: -1260 | EN12: -1532.2 | EO12: -1501.68 | EP12: -1373.84 | EQ12: -1101.83 | ER12: -342.13 | ES12: -119.269 | ET12: 77.6662 | EU12: 187.477 | EV12: 217.511 | EW12: 192.524 | EX12: 191.51 | EY12: 208.417 | EZ12: 160.332 | FA12: 61.3427 | FB12: -120.155 | FC12: 353.054 | FD12: 357.362 | FE12: -382.845 | FF12: -384.569 | FG12: 392.076 | FH12: 462.657 | FI12: -8527.07 | FJ12: -3217 | FK12: 441.751 | FL12: 0.0715248
A13: 5 | B13: 1 | C13: 3503930 | D13: SpliceInbRH | E13: 3908020 | F13: 3908021 | G13: 0 | H13: 0 | I13: 51.48 | J13: 2_101_0 | K13: CDR_Pivot_V161_rightdown_all | L13: SUBCASE 101 = STLN ULT (INTACT) :STLN ULT (INTACT) | M13: Simulation 1 | N13: 28859.525904303933 151.3403652336483 4078.510250219238 | O13: -9011.57 | P13: 40.0735 | Q13: -171.194 | R13: 8901.54 | S13: 28823.743177159224 152.9538442307419 4072.0226987848973 | T13: 28829.588127213978 152.30845263190446 4080.474186496629 | U13: 28835.433077268735 151.663061033067 4088.9256742083603 | V13: 28841.278027323493 151.0176694342296 4097.377161920092 | W13: 28847.12297737825 150.37227783539214 4105.828649631823 | X13: 28852.967927433005 149.7268862365547 4114.280137343555 | Y13: 28861.436068236133 149.7268862365547 4108.42367020556 | Z13: 28869.90420903926 149.7268862365547 4102.567203067564 | AA13: 28878.372349842386 149.7268862365547 4096.710735929569 | AB13: 28886.840490645514 149.7268862365547 4090.854268791574 | AC13: 28895.308631448643 149.7268862365547 4084.997801653579 | AD13: 28889.46368139389 150.37227783539214 4076.546313941847 | AE13: 28883.61873133913 151.0176694342296 4068.094826230116 | AF13: 28877.773781284373 151.663061033067 4059.643338518384 | AG13: 28871.928831229616 152.30845263190446 4051.191850806653 | AH13: 28866.08388117486 152.9538442307419 4042.740363094921 | AI13: 28857.615740371733 152.9538442307419 4048.5968302329165 | AJ13: 28849.147599568605 152.9538442307419 4054.4532973709115 | AK13: 28840.67945876548 152.9538442307419 4060.309764508907 | AL13: 28832.211317962352 152.9538442307419 4066.166231646902 | AM13: 0 | AN13: 0 | AO13: 0 | AP13: 0 | AQ13: 0 | AR13: 0 | AS13: 0 | AT13: 0 | AU13: 0 | AV13: 0 | AW13: 0 | AX13: 0 | AY13: 0 | AZ13: 0 | BA13: 0 | BB13: 0 | BC13: 0 | BD13: 0 | BE13: 0 | BF13: 0 | BG13: 0 | BH13: 0 | BI13: 0 | BJ13: 0 | BK13: 0 | BL13: 0 | BM13: 0 | BN13: 0 | BO13: 0 | BP13: 0 | BQ13: 0 | BR13: 0 | BS13: 0 | BT13: 0 | BU13: 0 | BV13: 0 | BW13: 0 | BX13: 0 | BY13: 0 | BZ13: 0 | CA13: 0 | CB13: 0 | CC13: 0 | CD13: 0 | CE13: 0 | CF13: 0 | CG13: 0 | CH13: 0 | CI13: 0 | CJ13: 0 | CK13: 0 | CL13: 0 | CM13: 0 | CN13: 0 | CO13: 0 | CP13: 0 | CQ13: 0 | CR13: 0 | CS13: 0 | CT13: 0 | CU13: 0 | CV13: 0 | CW13: 0 | CX13: 0 | CY13: 0 | CZ13: 0 | DA13: 0 | DB13: 0 | DC13: 0 | DD13: 0 | DE13: 0 | DF13: 0 | DG13: 0 | DH13: 0 | DI13: 0 | DJ13: 0 | DK13: 0 | DL13: 0 | DM13: 0 | DN13: 0 | DO13: 0 | DP13: 0 | DQ13: 0 | DR13: 0 | DS13: 0 | DT13: 0 | DU13: 0 | DV13: 0 | DW13: 0 | DX13: 0 | DY13: 0 | DZ13: 0 | EA13: 0 | EB13: 0 | EC13: 0 | ED13: 0 | EE13: 0 | EF13: 0 | EG13: 0 | EH13: 0 | EI13: 0 | EJ13: 0 | EK13: 0 | EL13: 0 | EM13: 0 | EN13: 0 | EO13: 0 | EP13: 0 | EQ13: 0 | ER13: 0 | ES13: 0 | ET13: 0 | EU13: 0 | EV13: 0 | EW13: 0 | EX13: 0 | EY13: 0 | EZ13: 0 | FA13: 0 | FB13: 0 | FC13: 0 | FD13: 0 | FE13: 0 | FF13: 0 | FG13: 0 | FH13: 0 | FI13: 0 | FJ13: 0 | FK13: 0 | FL13: 0
A14: 6 | B14: 1 | C14: 3503930 | D14: SpliceInbRH | E14: 3908020 | F14: 3908021 | G14: 0 | H14: 0 | I14: 51.48 | J14: 3_102_0 | K14: CDR_Pivot_V161_leftdown_all | L14: SUBCASE 102 = STLP ULT (INTACT) :STLP ULT (INTACT) | M14: Simulation 1 | N14: 28859.525904303933 151.3403652336483 4078.510250219238 | O14: 9229.85 | P14: 344.269 | Q14: 248.929 | R14: 0 | S14: 28823.743177159224 152.9538442307419 4072.0226987848973 | T14: 28829.588127213978 152.30845263190446 4080.474186496629 | U14: 28835.433077268735 151.663061033067 4088.9256742083603 | V14: 28841.278027323493 151.0176694342296 4097.377161920092 | W14: 28847.12297737825 150.37227783539214 4105.828649631823 | X14: 28852.967927433005 149.7268862365547 4114.280137343555 | Y14: 28861.436068236133 149.7268862365547 4108.42367020556 | Z14: 28869.90420903926 149.7268862365547 4102.567203067564 | AA14: 28878.372349842386 149.7268862365547 4096.710735929569 | AB14: 28886.840490645514 149.7268862365547 4090.854268791574 | AC14: 28895.308631448643 149.7268862365547 4084.997801653579 | AD14: 28889.46368139389 150.37227783539214 4076.546313941847 | AE14: 28883.61873133913 151.0176694342296 4068.094826230116 | AF14: 28877.773781284373 151.663061033067 4059.643338518384 | AG14: 28871.928831229616 152.30845263190446 4051.191850806653 | AH14: 28866.08388117486 152.9538442307419 4042.740363094921 | AI14: 28857.615740371733 152.9538442307419 4048.5968302329165 | AJ14: 28849.147599568605 152.9538442307419 4054.4532973709115 | AK14: 28840.67945876548 152.9538442307419 4060.309764508907 | AL14: 28832.211317962352 152.9538442307419 4066.166231646902 | AM14: 0 | AN14: 0 | AO14: 0 | AP14: 0 | AQ14: 0 | AR14: 0 | AS14: 0 | AT14: 0 | AU14: 0 | AV14: 0 | AW14: 0 | AX14: 0 | AY14: 0 | AZ14: 0 | BA14: 0 | BB14: 0 | BC14: 0 | BD14: 0 | BE14: 0 | BF14: 0 | BG14: 0 | BH14: 0 | BI14: 0 | BJ14: 0 | BK14: 0 | BL14: 0 | BM14: 0 | BN14: 0 | BO14: 0 | BP14: 0 | BQ14: 0 | BR14: 0 | BS14: 0 | BT14: 0 | BU14: 0 | BV14: 0 | BW14: 0 | BX14: 0 | BY14: 0 | BZ14: 0 | CA14: 0 | CB14: 0 | CC14: 0 | CD14: 0 | CE14: 0 | CF14: 0 | CG14: 0 | CH14: 0 | CI14: 0 | CJ14: 0 | CK14: 0 | CL14: 0 | CM14: 0 | CN14: 0 | CO14: 0 | CP14: 0 | CQ14: 0 | CR14: 0 | CS14: 0 | CT14: 0 | CU14: 0 | CV14: 0 | CW14: 0 | CX14: 0 | CY14: 0 | CZ14: 0 | DA14: 0 | DB14: 0 | DC14: 0 | DD14: 0 | DE14: 0 | DF14: 0 | DG14: 0 | DH14: 0 | DI14: 0 | DJ14: 0 | DK14: 0 | DL14: 0 | DM14: 0 | DN14: 0 | DO14: 0 | DP14: 0 | DQ14: 0 | DR14: 0 | DS14: 0 | DT14: 0 | DU14: 0 | DV14: 0 | DW14: 0 | DX14: 0 | DY14: 0 | DZ14: 0 | EA14: 0 | EB14: 0 | EC14: 0 | ED14: 0 | EE14: 0 | EF14: 0 | EG14: 0 | EH14: 0 | EI14: 0 | EJ14: 0 | EK14: 0 | EL14: 0 | EM14: 0 | EN14: 0 | EO14: 0 | EP14: 0 | EQ14: 0 | ER14: 0 | ES14: 0 | ET14: 0 | EU14: 0 | EV14: 0 | EW14: 0 | EX14: 0 | EY14: 0 | EZ14: 0 | FA14: 0 | FB14: 0 | FC14: 0 | FD14: 0 | FE14: 0 | FF14: 0 | FG14: 0 | FH14: 0 | FI14: 0 | FJ14: 0 | FK14: 0 | FL14: 0
A15: 7 | B15: 2 | C15: 2101253 | D15: SpliceOutbLH | E15: 2915010 | F15: 2915010 | G15: 0 | H15: 0 | I15: 51.48 | J15: 2_101_0 | K15: CDR_Pivot_V161_rightdown_all | L15: SUBCASE 101 = STLN ULT (INTACT) :STLN ULT (INTACT) | M15: Simulation 1 | N15: 28852.61859534529 -177.25256712851655 3918.433981082009 | O15: -5159.54 | P15: -11773.5 | Q15: -251.052 | R15: 34172.2 | S15: 28816.390556136725 -178.76567858189 3915.2191920015052 | T15: 28824.26658016535 -178.16043400054062 3908.615440000008 | U15: 28832.142604193974 -177.55518941919124 3902.011687998511 | V15: 28840.018628222595 -176.94994483784185 3895.407935997014 | W15: 28847.89465225122 -176.34470025649247 3888.804183995517 | X15: 28855.770676279844 -175.7394556751431 3882.20043199402 | Y15: 28862.38586793465 -175.7394556751431 3890.0900996277187 | Z15: 28869.00105958945 -175.7394556751431 3897.9797672614172 | AA15: 28875.616251244253 -175.7394556751431 3905.8694348951153 | AB15: 28882.231442899054 -175.7394556751431 3913.759102528814 | AC15: 28888.846634553858 -175.7394556751431 3921.6487701625124 | AD15: 28880.970610525233 -176.34470025649247 3928.2525221640094 | AE15: 28873.09458649661 -176.94994483784185 3934.8562741655064 | AF15: 28865.218562467988 -177.55518941919124 3941.4600261670034 | AG15: 28857.342538439363 -178.16043400054062 3948.0637781685004 | AH15: 28849.46651441074 -178.76567858189 3954.6675301699975 | AI15: 28842.851322755934 -178.76567858189 3946.777862536299 | AJ15: 28836.236131101134 -178.76567858189 3938.8881949026004 | AK15: 28829.62093944633 -178.76567858189 3930.9985272689023 | AL15: 28823.00574779153 -178.76567858189 3923.1088596352038 | AM15: 0 | AN15: 0 | AO15: 0 | AP15: 0 | AQ15: 0 | AR15: 0 | AS15: 0 | AT15: 0 | AU15: 0 | AV15: 0 | AW15: 0 | AX15: 0 | AY15: 0 | AZ15: 0 | BA15: 0 | BB15: 0 | BC15: 0 | BD15: 0 | BE15: 0 | BF15: 0 | BG15: 0 | BH15: 0 | BI15: 0 | BJ15: 0 | BK15: 0 | BL15: 0 | BM15: 0 | BN15: 0 | BO15: 0 | BP15: 0 | BQ15: 0 | BR15: 0 | BS15: 0 | BT15: 0 | BU15: 0 | BV15: 0 | BW15: 0 | BX15: 0 | BY15: 0 | BZ15: 0 | CA15: 0 | CB15: 0 | CC15: 0 | CD15: 0 | CE15: 0 | CF15: 0 | CG15: 0 | CH15: 0 | CI15: 0 | CJ15: 0 | CK15: 0 | CL15: 0 | CM15: 0 | CN15: 0 | CO15: 0 | CP15: 0 | CQ15: 0 | CR15: 0 | CS15: 0 | CT15: 0 | CU15: 0 | CV15: 0 | CW15: 0 | CX15: 0 | CY15: 0 | CZ15: 0 | DA15: 0 | DB15: 0 | DC15: 0 | DD15: 0 | DE15: 0 | DF15: 0 | DG15: 0 | DH15: 0 | DI15: 0 | DJ15: 0 | DK15: 0 | DL15: 0 | DM15: 0 | DN15: 0 | DO15: 0 | DP15: 0 | DQ15: 0 | DR15: 0 | DS15: 0 | DT15: 0 | DU15: 0 | DV15: 0 | DW15: 0 | DX15: 0 | DY15: 0 | DZ15: 0 | EA15: 0 | EB15: 0 | EC15: 0 | ED15: 0 | EE15: 0 | EF15: 0 | EG15: 0 | EH15: 0 | EI15: 0 | EJ15: 0 | EK15: 0 | EL15: 0 | EM15: 0 | EN15: 0 | EO15: 0 | EP15: 0 | EQ15: 0 | ER15: 0 | ES15: 0 | ET15: 0 | EU15: 0 | EV15: 0 | EW15: 0 | EX15: 0 | EY15: 0 | EZ15: 0 | FA15: 0 | FB15: 0 | FC15: 0 | FD15: 0 | FE15: 0 | FF15: 0 | FG15: 0 | FH15: 0 | FI15: 0 | FJ15: 0 | FK15: 0 | FL15: 0
A16: 8 | B16: 2 | C16: 2101253 | D16: SpliceOutbLH | E16: 2915010 | F16: 2915010 | G16: 0 | H16: 0 | I16: 51.48 | J16: 3_102_0 | K16: CDR_Pivot_V161_leftdown_all | L16: SUBCASE 102 = STLP ULT (INTACT) :STLP ULT (INTACT) | M16: Simulation 1 | N16: 28852.61859534529 -177.25256712851655 3918.433981082009 | O16: 6401.09 | P16: 12292.4 | Q16: 361.743 | R16: 12578.8 | S16: 28816.390556136725 -178.76567858189 3915.2191920015052 | T16: 28824.26658016535 -178.16043400054062 3908.615440000008 | U16: 28832.142604193974 -177.55518941919124 3902.011687998511 | V16: 28840.018628222595 -176.94994483784185 3895.407935997014 | W16: 28847.89465225122 -176.34470025649247 3888.804183995517 | X16: 28855.770676279844 -175.7394556751431 3882.20043199402 | Y16: 28862.38586793465 -175.7394556751431 3890.0900996277187 | Z16: 28869.00105958945 -175.7394556751431 3897.9797672614172 | AA16: 28875.616251244253 -175.7394556751431 3905.8694348951153 | AB16: 28882.231442899054 -175.7394556751431 3913.759102528814 | AC16: 28888.846634553858 -175.7394556751431 3921.6487701625124 | AD16: 28880.970610525233 -176.34470025649247 3928.2525221640094 | AE16: 28873.09458649661 -176.94994483784185 3934.8562741655064 | AF16: 28865.218562467988 -177.55518941919124 3941.4600261670034 | AG16: 28857.342538439363 -178.16043400054062 3948.0637781685004 | AH16: 28849.46651441074 -178.76567858189 3954.6675301699975 | AI16: 28842.851322755934 -178.76567858189 3946.777862536299 | AJ16: 28836.236131101134 -178.76567858189 3938.8881949026004 | AK16: 28829.62093944633 -178.76567858189 3930.9985272689023 | AL16: 28823.00574779153 -178.76567858189 3923.1088596352038 | AM16: 0 | AN16: 0 | AO16: 0 | AP16: 0 | AQ16: 0 | AR16: 0 | AS16: 0 | AT16: 0 | AU16: 0 | AV16: 0 | AW16: 0 | AX16: 0 | AY16: 0 | AZ16: 0 | BA16: 0 | BB16: 0 | BC16: 0 | BD16: 0 | BE16: 0 | BF16: 0 | BG16: 0 | BH16: 0 | BI16: 0 | BJ16: 0 | BK16: 0 | BL16: 0 | BM16: 0 | BN16: 0 | BO16: 0 | BP16: 0 | BQ16: 0 | BR16: 0 | BS16: 0 | BT16: 0 | BU16: 0 | BV16: 0 | BW16: 0 | BX16: 0 | BY16: 0 | BZ16: 0 | CA16: 0 | CB16: 0 | CC16: 0 | CD16: 0 | CE16: 0 | CF16: 0 | CG16: 0 | CH16: 0 | CI16: 0 | CJ16: 0 | CK16: 0 | CL16: 0 | CM16: 0 | CN16: 0 | CO16: 0 | CP16: 0 | CQ16: 0 | CR16: 0 | CS16: 0 | CT16: 0 | CU16: 0 | CV16: 0 | CW16: 0 | CX16: 0 | CY16: 0 | CZ16: 0 | DA16: 0 | DB16: 0 | DC16: 0 | DD16: 0 | DE16: 0 | DF16: 0 | DG16: 0 | DH16: 0 | DI16: 0 | DJ16: 0 | DK16: 0 | DL16: 0 | DM16: 0 | DN16: 0 | DO16: 0 | DP16: 0 | DQ16: 0 | DR16: 0 | DS16: 0 | DT16: 0 | DU16: 0 | DV16: 0 | DW16: 0 | DX16: 0 | DY16: 0 | DZ16: 0 | EA16: 0 | EB16: 0 | EC16: 0 | ED16: 0 | EE16: 0 | EF16: 0 | EG16: 0 | EH16: 0 | EI16: 0 | EJ16: 0 | EK16: 0 | EL16: 0 | EM16: 0 | EN16: 0 | EO16: 0 | EP16: 0 | EQ16: 0 | ER16: 0 | ES16: 0 | ET16: 0 | EU16: 0 | EV16: 0 | EW16: 0 | EX16: 0 | EY16: 0 | EZ16: 0 | FA16: 0 | FB16: 0 | FC16: 0 | FD16: 0 | FE16: 0 | FF16: 0 | FG16: 0 | FH16: 0 | FI16: 0 | FJ16: 0 | FK16: 0 | FL16: 0
A17: 9 | B17: 2 | C17: 1101897 | D17: SkinLH | E17: 2915010 | F17: 1915012 | G17: 3915010 | H17: 1915011 | I17: 57.915 | J17: 2_101_0 | K17: CDR_Pivot_V161_rightdown_all | L17: SUBCASE 101 = STLN ULT (INTACT) :STLN ULT (INTACT) | M17: Simulation 1 | N17: 28852.61859534529 -167.8821762210271 3918.433981082009 | O17: -1087.15 | P17: -2631.61 | Q17: 1851.82 | R17: 34172.2 | S17: 28854.456133776413 -169.56765807719276 3877.557872951137 | T17: 28862.264459536942 -168.8934653347265 3886.0867299650317 | U17: 28870.07278529747 -168.21927259226024 3894.6155869789263 | V17: 28877.881111058003 -167.54507984979395 3903.144443992821 | W17: 28885.68943681853 -166.8708871073277 3911.6733010067155 | X17: 28893.49776257906 -166.19669436486143 3920.20215802061 | Y17: 28884.95442144608 -166.19669436486143 3928.023744259064 | Z17: 28876.411080313104 -166.19669436486143 3935.8453304975183 | AA17: 28867.867739180125 -166.19669436486143 3943.6669167359723 | AB17: 28859.32439804715 -166.19669436486143 3951.4885029744264 | AC17: 28850.78105691417 -166.19669436486143 3959.3100892128805 | AD17: 28842.97273115364 -166.8708871073277 3950.781232198986 | AE17: 28835.164405393112 -167.54507984979395 3942.2523751850913 | AF17: 28827.35607963258 -168.21927259226024 3933.7235181711967 | AG17: 28819.54775387205 -168.8934653347265 3925.194661157302 | AH17: 28811.739428111523 -169.56765807719276 3916.6658041434075 | AI17: 28820.282769244503 -169.56765807719276 3908.8442179049534 | AJ17: 28828.82611037748 -169.56765807719276 3901.0226316664994 | AK17: 28837.369451510458 -169.56765807719276 3893.2010454280453 | AL17: 28845.912792643434 -169.56765807719276 3885.379459189591 | AM17: 2025.72 | AN17: 2018.33 | AO17: 1990.67 | AP17: 1963.86 | AQ17: 1937.8 | AR17: 1908.34 | AS17: 1794.9 | AT17: 1696.08 | AU17: 1581.64 | AV17: 1461.1 | AW17: 1344.13 | AX17: 1349.15 | AY17: 1354.95 | AZ17: 1357.78 | BA17: 1355.21 | BB17: 1352.14 | BC17: 1470.94 | BD17: 1593.46 | BE17: 1726.86 | BF17: 1868.86 | BG17: -172.364 | BH17: -159.044 | BI17: -147.03 | BJ17: -138.602 | BK17: -134.316 | BL17: -128.335 | BM17: -146.93 | BN17: -171.03 | BO17: -191.185 | BP17: -214.377 | BQ17: -235.486 | BR17: -243.861 | BS17: -250.069 | BT17: -251.301 | BU17: -249.58 | BV17: -249.387 | BW17: -232.611 | BX17: -213.025 | BY17: -195.897 | BZ17: -182.498 | CA17: -334.417 | CB17: -336.26 | CC17: -333.756 | CD17: -335.305 | CE17: -343.063 | CF17: -357.103 | CG17: -384.87 | CH17: -411.71 | CI17: -427.087 | CJ17: -432.609 | CK17: -437.432 | CL17: -419.171 | CM17: -404.243 | CN17: -393.055 | CO17: -381.616 | CP17: -367.62 | CQ17: -366.216 | CR17: -360.927 | CS17: -352.213 | CT17: -343.085 | CU17: 518.344 | CV17: 666.702 | CW17: 342.564 | CX17: 150.229 | CY17: 337.775 | CZ17: 1047.5 | DA17: 1264.01 | DB17: 1615.65 | DC17: 1792.68 | DD17: 2133.85 | DE17: 2945.51 | DF17: 2531.47 | DG17: 2417.81 | DH17: 2473.55 | DI17: 2350.82 | DJ17: 1952.51 | DK17: 2015.03 | DL17: 1894.62 | DM17: 1604.59 | DN17: 1161.87 | DO17: -641.445 | DP17: -848.07 | DQ17: -797.247 | DR17: -619.993 | DS17: -532.162 | DT17: -481.925 | DU17: -253.882 | DV17: 168.6 | DW17: 956.157 | DX17: 1838.02 | DY17: 2265.99 | DZ17: 2215.15 | EA17: 2068.36 | EB17: 1866.56 | EC17: 1689.11 | ED17: 1531.6 | EE17: 1647.84 | EF17: 1553.32 | EG17: 871.4 | EH17: 10.7295 | EI17: 131.398 | EJ17: -195.882 | EK17: -326.654 | EL17: -203.71 | EM17: -30.0959 | EN17: 11.8708 | EO17: 93.7507 | EP17: -147.336 | EQ17: -532.565 | ER17: -513.404 | ES17: -287.195 | ET17: 26.1416 | EU17: 220.967 | EV17: 221.675 | EW17: 86.7713 | EX17: -11.3093 | EY17: 66.9731 | EZ17: 280.713 | FA17: 456.319 | FB17: 367.52 | FC17: 1631.03 | FD17: 1673 | FE17: -146.615 | FF17: -246.614 | FG17: -339.984 | FH17: -408.469 | FI17: -1662.18 | FJ17: -642.994 | FK17: 18.3037 | FL17: 0
A18: 10 | B18: 2 | C18: 1101897 | D18: SkinLH | E18: 2915010 | F18: 1915012 | G18: 3915010 | H18: 1915011 | I18: 57.915 | J18: 3_102_0 | K18: CDR_Pivot_V161_leftdown_all | L18: SUBCASE 102 = STLP ULT (INTACT) :STLP ULT (INTACT) | M18: Simulation 1 | N18: 28852.61859534529 -167.8821762210271 3918.433981082009 | O18: 2633.15 | P18: 3153.74 | Q18: -1763.74 | R18: 12578.8 | S18: 28854.456133776413 -169.56765807719276 3877.557872951137 | T18: 28862.264459536942 -168.8934653347265 3886.0867299650317 | U18: 28870.07278529747 -168.21927259226024 3894.6155869789263 | V18: 28877.881111058003 -167.54507984979395 3903.144443992821 | W18: 28885.68943681853 -166.8708871073277 3911.6733010067155 | X18: 28893.49776257906 -166.19669436486143 3920.20215802061 | Y18: 28884.95442144608 -166.19669436486143 3928.023744259064 | Z18: 28876.411080313104 -166.19669436486143 3935.8453304975183 | AA18: 28867.867739180125 -166.19669436486143 3943.6669167359723 | AB18: 28859.32439804715 -166.19669436486143 3951.4885029744264 | AC18: 28850.78105691417 -166.19669436486143 3959.3100892128805 | AD18: 28842.97273115364 -166.8708871073277 3950.781232198986 | AE18: 28835.164405393112 -167.54507984979395 3942.2523751850913 | AF18: 28827.35607963258 -168.21927259226024 3933.7235181711967 | AG18: 28819.54775387205 -168.8934653347265 3925.194661157302 | AH18: 28811.739428111523 -169.56765807719276 3916.6658041434075 | AI18: 28820.282769244503 -169.56765807719276 3908.8442179049534 | AJ18: 28828.82611037748 -169.56765807719276 3901.0226316664994 | AK18: 28837.369451510458 -169.56765807719276 3893.2010454280453 | AL18: 28845.912792643434 -169.56765807719276 3885.379459189591 | AM18: -2115.15 | AN18: -2122.75 | AO18: -2111.55 | AP18: -2103.83 | AQ18: -2100.78 | AR18: -2098.49 | AS18: -1951.83 | AT18: -1813.51 | AU18: -1651.91 | AV18: -1480.64 | AW18: -1320.03 | AX18: -1332.38 | AY18: -1345.01 | AZ18: -1352.48 | BA18: -1351.87 | BB18: -1349.66 | BC18: -1482.13 | BD18: -1618.91 | BE18: -1772.95 | BF18: -1939.02 | BG18: 229.235 | BH18: 223.573 | BI18: 218.759 | BJ18: 218.853 | BK18: 225.251 | BL18: 232.525 | BM18: 236.475 | BN18: 244.679 | BO18: 245.777 | BP18: 248.876 | BQ18: 252.771 | BR18: 263.29 | BS18: 272.057 | BT18: 274.599 | BU18: 272.082 | BV18: 269.709 | BW18: 259.992 | BX18: 246.577 | BY18: 237.247 | BZ18: 232.766 | CA18: 301.245 | CB18: 297.127 | CC18: 286.702 | CD18: 278.137 | CE18: 274.211 | CF18: 275.309 | CG18: 279.307 | CH18: 293.187 | CI18: 306.794 | CJ18: 315.885 | CK18: 326.703 | CL18: 323.311 | CM18: 322.457 | CN18: 324.372 | CO18: 324.275 | CP18: 319.123 | CQ18: 317.281 | CR18: 311.24 | CS18: 302.304 | CT18: 298.6 | CU18: -739.156 | CV18: -874.92 | CW18: -502.673 | CX18: -279.446 | CY18: -462.85 | CZ18: -1194.92 | DA18: -1416.6 | DB18: -1772.22 | DC18: -1923.04 | DD18: -2259.19 | DE18: -3096.77 | DF18: -2722.87 | DG18: -2660.19 | DH18: -2756.23 | DI18: -2637.02 | DJ18: -2213.41 | DK18: -2298.97 | DL18: -2184.31 | DM18: -1888.7 | DN18: -1423.94 | DO18: 386.087 | DP18: 598.91 | DQ18: 531.915 | DR18: 328.973 | DS18: 223.425 | DT18: 157.56 | DU18: -31.9828 | DV18: -448.635 | DW18: -1249.33 | DX18: -2114.74 | DY18: -2450.67 | DZ18: -2420.02 | EA18: -2284.38 | EB18: -2085.88 | EC18: -1908.2 | ED18: -1745.89 | EE18: -1944.09 | EF18: -1889.42 | EG18: -1177.59 | EH18: -278.106 | EI18: -86.6728 | EJ18: 270.623 | EK18: 411.067 | EL18: 273.138 | EM18: 83.9071 | EN18: 43.0372 | EO18: -23.228 | EP18: 258.277 | EQ18: 679.613 | ER18: 649.86 | ES18: 394.081 | ET18: 55.09 | EU18: -152.204 | EV18: -147.402 | EW18: 0.587095 | EX18: 103.86 | EY18: 14.6375 | EZ18: -231.655 | FA18: -430.316 | FB18: -335.65 | FC18: -1712.97 | FD18: -1719.4 | FE18: 224.699 | FF18: 267.418 | FG18: 285.455 | FH18: 323.373 | FI18: 1867.6 | FJ18: 889.014 | FK18: -95.2065 | FL18: 0
A19: 11 | B19: 2 | C19: 3102461 | D19: SpliceInbLH | E19: 3915010 | F19: 3915012 | G19: 4915010 | H19: 3915013 | I19: 51.48 | J19: 2_101_0 | K19: CDR_Pivot_V161_rightdown_all | L19: SUBCASE 101 = STLN ULT (INTACT) :STLN ULT (INTACT) | M19: Simulation 1 | N19: 28852.61859534529 -158.1810207933401 3918.433981082009 | O19: 22736.6 | P19: -11524.5 | Q19: -467.47 | R19: 34172.2 | S19: 28888.446187447833 -156.7918424016929 3924.7227828383166 | T19: 28882.548878840567 -157.34751375835177 3916.301346112076 | U19: 28876.651570233305 -157.90318511501067 3907.8799093858347 | V19: 28870.75426162604 -158.45885647166955 3899.4584726595936 | W19: 28864.856953018778 -159.01452782832845 3891.0370359333524 | X19: 28858.959644411512 -159.57019918498733 3882.6155992071117 | Y19: 28850.52591617776 -159.57019918498733 3888.5215152308297 | Z19: 28842.092187944007 -159.57019918498733 3894.4274312545476 | AA19: 28833.658459710256 -159.57019918498733 3900.333347278265 | AB19: 28825.2247314765 -159.57019918498733 3906.239263301983 | AC19: 28816.79100324275 -159.57019918498733 3912.145179325701 | AD19: 28822.688311850015 -159.01452782832845 3920.5666160519418 | AE19: 28828.585620457277 -158.45885647166955 3928.988052778183 | AF19: 28834.482929064543 -157.90318511501067 3937.409489504424 | AG19: 28840.380237671805 -157.34751375835177 3945.830926230665 | AH19: 28846.27754627907 -156.7918424016929 3954.252362956906 | AI19: 28854.71127451282 -156.7918424016929 3948.346446933188 | AJ19: 28863.145002746576 -156.7918424016929 3942.44053090947 | AK19: 28871.578730980327 -156.7918424016929 3936.5346148857525 | AL19: 28880.012459214082 -156.7918424016929 3930.6286988620345 | AM19: 0 | AN19: 0 | AO19: 0 | AP19: 0 | AQ19: 0 | AR19: 0 | AS19: 0 | AT19: 0 | AU19: 0 | AV19: 0 | AW19: 0 | AX19: 0 | AY19: 0 | AZ19: 0 | BA19: 0 | BB19: 0 | BC19: 0 | BD19: 0 | BE19: 0 | BF19: 0 | BG19: 0 | BH19: 0 | BI19: 0 | BJ19: 0 | BK19: 0 | BL19: 0 | BM19: 0 | BN19: 0 | BO19: 0 | BP19: 0 | BQ19: 0 | BR19: 0 | BS19: 0 | BT19: 0 | BU19: 0 | BV19: 0 | BW19: 0 | BX19: 0 | BY19: 0 | BZ19: 0 | CA19: 0 | CB19: 0 | CC19: 0 | CD19: 0 | CE19: 0 | CF19: 0 | CG19: 0 | CH19: 0 | CI19: 0 | CJ19: 0 | CK19: 0 | CL19: 0 | CM19: 0 | CN19: 0 | CO19: 0 | CP19: 0 | CQ19: 0 | CR19: 0 | CS19: 0 | CT19: 0 | CU19: 0 | CV19: 0 | CW19: 0 | CX19: 0 | CY19: 0 | CZ19: 0 | DA19: 0 | DB19: 0 | DC19: 0 | DD19: 0 | DE19: 0 | DF19: 0 | DG19: 0 | DH19: 0 | DI19: 0 | DJ19: 0 | DK19: 0 | DL19: 0 | DM19: 0 | DN19: 0 | DO19: 0 | DP19: 0 | DQ19: 0 | DR19: 0 | DS19: 0 | DT19: 0 | DU19: 0 | DV19: 0 | DW19: 0 | DX19: 0 | DY19: 0 | DZ19: 0 | EA19: 0 | EB19: 0 | EC19: 0 | ED19: 0 | EE19: 0 | EF19: 0 | EG19: 0 | EH19: 0 | EI19: 0 | EJ19: 0 | EK19: 0 | EL19: 0 | EM19: 0 | EN19: 0 | EO19: 0 | EP19: 0 | EQ19: 0 | ER19: 0 | ES19: 0 | ET19: 0 | EU19: 0 | EV19: 0 | EW19: 0 | EX19: 0 | EY19: 0 | EZ19: 0 | FA19: 0 | FB19: 0 | FC19: 0 | FD19: 0 | FE19: 0 | FF19: 0 | FG19: 0 | FH19: 0 | FI19: 0 | FJ19: 0 | FK19: 0 | FL19: 0
A20: 12 | B20: 2 | C20: 3102461 | D20: SpliceInbLH | E20: 3915010 | F20: 3915012 | G20: 4915010 | H20: 3915013 | I20: 51.48 | J20: 3_102_0 | K20: CDR_Pivot_V161_leftdown_all | L20: SUBCASE 102 = STLP ULT (INTACT) :STLP ULT (INTACT) | M20: Simulation 1 | N20: 28852.61859534529 -158.1810207933401 3918.433981082009 | O20: -21167.1 | P20: 13857.1 | Q20: 556.109 | R20: 12578.8 | S20: 28888.446187447833 -156.7918424016929 3924.7227828383166 | T20: 28882.548878840567 -157.34751375835177 3916.301346112076 | U20: 28876.651570233305 -157.90318511501067 3907.8799093858347 | V20: 28870.75426162604 -158.45885647166955 3899.4584726595936 | W20: 28864.856953018778 -159.01452782832845 3891.0370359333524 | X20: 28858.959644411512 -159.57019918498733 3882.6155992071117 | Y20: 28850.52591617776 -159.57019918498733 3888.5215152308297 | Z20: 28842.092187944007 -159.57019918498733 3894.4274312545476 | AA20: 28833.658459710256 -159.57019918498733 3900.333347278265 | AB20: 28825.2247314765 -159.57019918498733 3906.239263301983 | AC20: 28816.79100324275 -159.57019918498733 3912.145179325701 | AD20: 28822.688311850015 -159.01452782832845 3920.5666160519418 | AE20: 28828.585620457277 -158.45885647166955 3928.988052778183 | AF20: 28834.482929064543 -157.90318511501067 3937.409489504424 | AG20: 28840.380237671805 -157.34751375835177 3945.830926230665 | AH20: 28846.27754627907 -156.7918424016929 3954.252362956906 | AI20: 28854.71127451282 -156.7918424016929 3948.346446933188 | AJ20: 28863.145002746576 -156.7918424016929 3942.44053090947 | AK20: 28871.578730980327 -156.7918424016929 3936.5346148857525 | AL20: 28880.012459214082 -156.7918424016929 3930.6286988620345 | AM20: 0 | AN20: 0 | AO20: 0 | AP20: 0 | AQ20: 0 | AR20: 0 | AS20: 0 | AT20: 0 | AU20: 0 | AV20: 0 | AW20: 0 | AX20: 0 | AY20: 0 | AZ20: 0 | BA20: 0 | BB20: 0 | BC20: 0 | BD20: 0 | BE20: 0 | BF20: 0 | BG20: 0 | BH20: 0 | BI20: 0 | BJ20: 0 | BK20: 0 | BL20: 0 | BM20: 0 | BN20: 0 | BO20: 0 | BP20: 0 | BQ20: 0 | BR20: 0 | BS20: 0 | BT20: 0 | BU20: 0 | BV20: 0 | BW20: 0 | BX20: 0 | BY20: 0 | BZ20: 0 | CA20: 0 | CB20: 0 | CC20: 0 | CD20: 0 | CE20: 0 | CF20: 0 | CG20: 0 | CH20: 0 | CI20: 0 | CJ20: 0 | CK20: 0 | CL20: 0 | CM20: 0 | CN20: 0 | CO20: 0 | CP20: 0 | CQ20: 0 | CR20: 0 | CS20: 0 | CT20: 0 | CU20: 0 | CV20: 0 | CW20: 0 | CX20: 0 | CY20: 0 | CZ20: 0 | DA20: 0 | DB20: 0 | DC20: 0 | DD20: 0 | DE20: 0 | DF20: 0 | DG20: 0 | DH20: 0 | DI20: 0 | DJ20: 0 | DK20: 0 | DL20: 0 | DM20: 0 | DN20: 0 | DO20: 0 | DP20: 0 | DQ20: 0 | DR20: 0 | DS20: 0 | DT20: 0 | DU20: 0 | DV20: 0 | DW20: 0 | DX20: 0 | DY20: 0 | DZ20: 0 | EA20: 0 | EB20: 0 | EC20: 0 | ED20: 0 | EE20: 0 | EF20: 0 | EG20: 0 | EH20: 0 | EI20: 0 | EJ20: 0 | EK20: 0 | EL20: 0 | EM20: 0 | EN20: 0 | EO20: 0 | EP20: 0 | EQ20: 0 | ER20: 0 | ES20: 0 | ET20: 0 | EU20: 0 | EV20: 0 | EW20: 0 | EX20: 0 | EY20: 0 | EZ20: 0 | FA20: 0 | FB20: 0 | FC20: 0 | FD20: 0 | FE20: 0 | FF20: 0 | FG20: 0 | FH20: 0 | FI20: 0 | FJ20: 0 | FK20: 0 | FL20: 0
... A42: 34 | B42: 5 | C42: 4100254 | D42: RearSpar2 | E42: 4911010 | F42: 4911010 | G42: 0 | H42: 0 | I42: 57.915 | J42: 3_102_0 | K42: CDR_Pivot_V161_leftdown_all | L42: SUBCASE 102 = STLP ULT (INTACT) :STLP ULT (INTACT) | M42: Simulation 1 | N42: 28901.79903954942 -148.127 3972.3867144859933 | O42: -33342.2 | P42: 12142.1 | Q42: 2845.94 | R42: 20184 | S42: 28860.908177099216 -149.51095883006633 3970.6272718085615 | T42: 28868.725110526975 -148.9573752980398 3979.1569251461283 | U42: 28876.542043954734 -148.40379176601328 3987.6865784836955 | V42: 28884.35897738249 -147.85020823398673 3996.216231821262 | W42: 28892.17591081025 -147.2966247019602 4004.7458851588294 | X42: 28899.992844238008 -146.7430411699337 4013.275538496396 | Y42: 28908.53225579033 -146.7430411699337 4005.449662229802 | Z42: 28917.071667342654 -146.7430411699337 3997.623785963208 | AA42: 28925.611078894977 -146.7430411699337 3989.7979096966133 | AB42: 28934.1504904473 -146.7430411699337 3981.972033430019 | AC42: 28942.689901999624 -146.7430411699337 3974.146157163425 | AD42: 28934.872968571864 -147.2966247019602 3965.616503825858 | AE42: 28927.056035144105 -147.85020823398673 3957.086850488291 | AF42: 28919.23910171635 -148.40379176601328 3948.5571971507243 | AG42: 28911.42216828859 -148.9573752980398 3940.027543813157 | AH42: 28903.605234860832 -149.51095883006633 3931.4978904755903 | AI42: 28895.06582330851 -149.51095883006633 3939.3237667421845 | AJ42: 28886.526411756186 -149.51095883006633 3947.1496430087786 | AK42: 28877.987000203862 -149.51095883006633 3954.9755192753732 | AL42: 28869.44758865154 -149.51095883006633 3962.8013955419674 | AM42: -233.853 | AN42: -180.48 | AO42: -168.415 | AP42: -162.397 | AQ42: -115.565 | AR42: -58.0932 | AS42: -0.759476 | AT42: 45.7347 | AU42: 47.5674 | AV42: -10.8261 | AW42: -58.477 | AX42: -100.208 | AY42: -150.879 | AZ42: -191.033 | BA42: -259.271 | BB42: -334.335 | BC42: -318.542 | BD42: -274.104 | BE42: -239.177 | BF42: -228.958 | BG42: -23.5422 | BH42: -19.5148 | BI42: 5.04271 | BJ42: 23.4205 | BK42: -3.79152 | BL42: -86.7968 | BM42: -132.754 | BN42: -153.156 | BO42: -124.007 | BP42: -70.6665 | BQ42: -23.7027 | BR42: -25.8458 | BS42: -66.5068 | BT42: -126.764 | BU42: -113.002 | BV42: -55.2585 | BW42: -35.4067 | BX42: -14.5281 | BY42: -2.19362 | BZ42: -11.1358 | CA42: -33.1977 | CB42: -6.68137 | CC42: 2.84029 | CD42: -30.3948 | CE42: -106.318 | CF42: -134.517 | CG42: -91.0828 | CH42: -33.0344 | CI42: 42.3414 | CJ42: 63.0356 | CK42: 38.5572 | CL42: 76.3114 | CM42: 104.319 | CN42: 139.385 | CO42: 192.484 | CP42: 231.524 | CQ42: 213.084 | CR42: 128.512 | CS42: 44.8428 | CT42: -9.0929 | CU42: -213.045 | CV42: -224.038 | CW42: -177.619 | CX42: -70.036 | CY42: 62.955 | CZ42: 85.0054 | DA42: 10.886 | DB42: -63.6048 | DC42: -101.201 | DD42: -131.277 | DE42: -163.3 | DF42: -416.344 | DG42: -740.8 | DH42: -952.802 | DI42: -782.859 | DJ42: -510.299 | DK42: -395.305 | DL42: -269.343 | DM42: -179.49 | DN42: -180.423 | DO42: 6.83245 | DP42: -73.0472 | DQ42: -101.818 | DR42: -5.60607 | DS42: 197.881 | DT42: 185.569 | DU42: -12.2363 | DV42: -249.276 | DW42: -511.408 | DX42: -671.713 | DY42: -692.89 | DZ42: -825.542 | EA42: -929.792 | EB42: -947.85 | EC42: -902.277 | ED42: -827.176 | EE42: -715.878 | EF42: -488.645 | EG42: -263.864 | EH42: -99.7831 | EI42: 122.302 | EJ42: 42.1635 | EK42: 20.4315 | EL42: 33.6444 | EM42: 42.1254 | EN42: 44.2392 | EO42: -51.8074 | EP42: -135.117 | EQ42: -187.87 | ER42: -115.139 | ES42: -49.3875 | ET42: 25.7898 | EU42: 116.806 | EV42: 108.787 | EW42: 69.1472 | EX42: 49.2794 | EY42: 35.1675 | EZ42: 109.423 | FA42: 166.229 | FB42: 158.557 | FC42: -5.80895 | FD42: -271.495 | FE42: -17.5304 | FF42: -68.5134 | FG42: -19.1167 | FH42: 130.43 | FI42: 175.95 | FJ42: 409.643 | FK42: -32.1335 | FL42: 0
A43: 35 | B43: 6 | C43: 4100164 | D43: RearSpar2 | E43: 4916010 | F43: 4916010 | G43: 0 | H43: 0 | I43: 57.915 | J43: 2_101_0 | K43: CDR_Pivot_V161_rightdown_all | L43: SUBCASE 101 = STLN ULT (INTACT) :STLN ULT (INTACT) | M43: Simulation 1 | N43: 28910.19671926622 -146.897 3875.0115942784673 | O43: 34044 | P43: -8867.91 | Q43: -7692.11 | R43: 34305.2 | S43: 28869.29638238861 -147.9664086564381 3873.2530662224826 | T43: 28877.119162253206 -147.53864519386286 3881.7845973048957 | U43: 28884.9419421178 -147.1108817312876 3890.3161283873087 | V43: 28892.764721982396 -146.68311826871238 3898.847659469722 | W43: 28900.58750184699 -146.25535480613712 3907.3791905521352 | X43: 28908.410281711585 -145.8275913435619 3915.9107216345483 | Y43: 28916.947636598034 -145.8275913435619 3908.082601774529 | Z43: 28925.48499148448 -145.8275913435619 3900.2544819145096 | AA43: 28934.022346370934 -145.8275913435619 3892.4263620544907 | AB43: 28942.277248346312 -144.84386598146492 3884.8158160206995 | AC43: 28951.09705614383 -145.8275913435619 3876.770122334452 | AD43: 28943.274276279233 -146.25535480613712 3868.238591252039 | AE43: 28935.45149641464 -146.68311826871238 3859.707060169626 | AF43: 28927.628716550043 -147.1108817312876 3851.1755290872125 | AG43: 28919.80593668545 -147.53864519386286 3842.6439980047994 | AH43: 28911.983156820854 -147.9664086564381 3834.1124669223864 | AI43: 28903.043483942558 -146.79669175279253 3842.2631378076658 | AJ43: 28894.908447047957 -147.9664086564381 3849.768706642425 | AK43: 28886.371092161506 -147.9664086564381 3857.596826502444 | AL43: 28877.833737275058 -147.9664086564381 3865.4249463624633 | AM43: 610.83 | AN43: 583.646 | AO43: 557.765 | AP43: 510.761 | AQ43: 444.065 | AR43: 364.186 | AS43: 331.75 | AT43: 313.691 | AU43: 310.749 | AV43: 320.916 | AW43: 334.422 | AX43: 389.135 | AY43: 452.341 | AZ43: 506.955 | BA43: 558.998 | BB43: 623.843 | BC43: 583.725 | BD43: 566.545 | BE43: 575.362 | BF43: 594.49 | BG43: 86.4318 | BH43: 63.7244 | BI43: -7.46849 | BJ43: -67.1921 | BK43: -76.3384 | BL43: -24.8867 | BM43: -15.8087 | BN43: -13.4484 | BO43: -38.7649 | BP43: -99.4518 | BQ43: -139.825 | BR43: -99.7362 | BS43: -11.8275 | BT43: 83.2994 | BU43: 60.0896 | BV43: -16.4889 | BW43: -46.7746 | BX43: -53.3446 | BY43: -10.1764 | BZ43: 51.3193 | CA43: -232.85 | CB43: -230.665 | CC43: -234.89 | CD43: -210.548 | CE43: -182.176 | CF43: -158.379 | CG43: -151.124 | CH43: -217.847 | CI43: -311.66 | CJ43: -392.66 | CK43: -419.279 | CL43: -351.841 | CM43: -318.29 | CN43: -337.343 | CO43: -472.711 | CP43: -511.036 | CQ43: -449.14 | CR43: -371.99 | CS43: -303.768 | CT43: -251.262 | CU43: 183.474 | CV43: 412.21 | CW43: 323.952 | CX43: 110.936 | CY43: 6.51914 | CZ43: 100.123 | DA43: -11.0281 | DB43: -125.085 | DC43: -278.441 | DD43: -493.236 | DE43: -622.671 | DF43: -429.026 | DG43: -292.598 | DH43: -268.361 | DI43: -346.372 | DJ43: -331.195 | DK43: -301.429 | DL43: -209.508 | DM43: -66.3157 | DN43: 86.6006 | DO43: 23.581 | DP43: 229.61 | DQ43: 341.276 | DR43: 376.193 | DS43: 422.962 | DT43: 515.278 | DU43: 351.109 | DV43: 115.843 | DW43: -210.433 | DX43: -625.891 | DY43: -867.804 | DZ43: -689.278 | EA43: -719.864 | EB43: -928.886 | EC43: -916.493 | ED43: -659.749 | EE43: -427.363 | EF43: -136.198 | EG43: -12.2894 | EH43: 6.73911 | EI43: -79.8828 | EJ43: 36.2685 | EK43: 150.899 | EL43: 150.508 | EM43: 57.222 | EN43: -100.915 | EO43: -10.9887 | EP43: 174.111 | EQ43: 330.605 | ER43: 377.317 | ES43: 311.802 | ET43: 20.0416 | EU43: -90.2419 | EV43: 26.5694 | EW43: 403.83 | EX43: 454.364 | EY43: 457.621 | EZ43: 343.28 | FA43: 171.601 | FB43: -6.11387 | FC43: 329.286 | FD43: 592.466 | FE43: -4.28823 | FF43: -20.7481 | FG43: -208.251 | FH43: -401.75 | FI43: 172.393 | FJ43: 239.431 | FK43: -156.803 | FL43: 0 | FM43: Pt10 17 modified
A44: 36 | B44: 6 | C44: 4100164 | D44: RearSpar2 | E44: 4916010 | F44: 4916010 | G44: 0 | H44: 0 | I44: 57.915 | J44: 3_102_0 | K44: CDR_Pivot_V161_leftdown_all | L44: SUBCASE 102 = STLP ULT (INTACT) :STLP ULT (INTACT) | M44: Simulation 1 | N44: 28910.19671926622 -146.897 3875.0115942784673 | O44: -33377.3 | P44: 9260.79 | Q44: 7587.23 | R44: 14200.5 | S44: 28869.29638238861 -147.9664086564381 3873.2530662224826 | T44: 28877.119162253206 -147.53864519386286 3881.7845973048957 | U44: 28884.9419421178 -147.1108817312876 3890.3161283873087 | V44: 28892.764721982396 -146.68311826871238 3898.847659469722 | W44: 28900.58750184699 -146.25535480613712 3907.3791905521352 | X44: 28908.410281711585 -145.8275913435619 3915.9107216345483 | Y44: 28916.947636598034 -145.8275913435619 3908.082601774529 | Z44: 28925.48499148448 -145.8275913435619 3900.2544819145096 | AA44: 28934.022346370934 -145.8275913435619 3892.4263620544907 | AB44: 28942.277248346312 -144.84386598146492 3884.8158160206995 | AC44: 28951.09705614383 -145.8275913435619 3876.770122334452 | AD44: 28943.274276279233 -146.25535480613712 3868.238591252039 | AE44: 28935.45149641464 -146.68311826871238 3859.707060169626 | AF44: 28927.628716550043 -147.1108817312876 3851.1755290872125 | AG44: 28919.80593668545 -147.53864519386286 3842.6439980047994 | AH44: 28911.983156820854 -147.9664086564381 3834.1124669223864 | AI44: 28903.043483942558 -146.79669175279253 3842.2631378076658 | AJ44: 28894.908447047957 -147.9664086564381 3849.768706642425 | AK44: 28886.371092161506 -147.9664086564381 3857.596826502444 | AL44: 28877.833737275058 -147.9664086564381 3865.4249463624633 | AM44: -595.732 | AN44: -570.951 | AO44: -547.594 | AP44: -502.316 | AQ44: -436.926 | AR44: -358.012 | AS44: -325.193 | AT44: -306.163 | AU44: -301.537 | AV44: -309.509 | AW44: -321.773 | AX44: -372.911 | AY44: -434.392 | AZ44: -489.225 | BA44: -542.047 | BB44: -606.525 | BC44: -567.05 | BD44: -549.444 | BE44: -557.663 | BF44: -577.174 | BG44: -88.0443 | BH44: -63.3199 | BI44: 9.23728 | BJ44: 69.4898 | BK44: 79.1152 | BL44: 28.386 | BM44: 20.0711 | BN44: 18.9123 | BO44: 44.95 | BP44: 105.174 | BQ44: 144.414 | BR44: 106.034 | BS44: 18.0904 | BT44: -78.9278 | BU44: -58.3833 | BV44: 17.3392 | BW44: 46.916 | BX44: 51.9699 | BY44: 7.91712 | BZ44: -53.6297 | CA44: 242.39 | CB44: 239.27 | CC44: 241.038 | CD44: 214.463 | CE44: 184.476 | CF44: 159.799 | CG44: 152.373 | CH44: 218.125 | CI44: 311.16 | CJ44: 392.324 | CK44: 419.851 | CL44: 351.578 | CM44: 318.821 | CN44: 340.466 | CO44: 479.95 | CP44: 520.814 | CQ44: 458.599 | CR44: 381.537 | CS44: 313.679 | CT44: 261.324 | CU44: -200.46 | CV44: -434.101 | CW44: -341.112 | CX44: -118.875 | CY44: -9.36834 | CZ44: -105.462 | DA44: 4.21744 | DB44: 114.893 | DC44: 265.807 | DD44: 481.16 | DE44: 612.825 | DF44: 421.274 | DG44: 280.346 | DH44: 249.205 | DI44: 328.924 | DJ44: 318.337 | DK44: 290.359 | DL44: 200.327 | DM44: 54.8936 | DN44: -101.746 | DO44: -49.9529 | DP44: -258.93 | DQ44: -370.976 | DR44: -405.514 | DS44: -451.73 | DT44: -544.275 | DU44: -384.852 | DV44: -152.516 | DW44: 171.985 | DX44: 586.932 | DY44: 831.823 | DZ44: 650.481 | EA44: 679.654 | EB44: 891.856 | EC44: 892.366 | ED44: 640.425 | EE44: 404.254 | EF44: 109.382 | EG44: -17.0657 | EH44: -35.9829 | EI44: 98.3407 | EJ44: -23.3942 | EK44: -145.98 | EL44: -144.523 | EM44: -43.5323 | EN44: 126.653 | EO44: 36.828 | EP44: -156.654 | EQ44: -325.598 | ER44: -384.458 | ES44: -322.538 | ET44: -21.1908 | EU44: 98.9774 | EV44: -11.1842 | EW44: -397.384 | EX44: -455.259 | EY44: -460.06 | EZ44: -342.539 | FA44: -163.888 | FB44: 21.2988 | FC44: -320.365 | FD44: -575.598 | FE44: 5.81066 | FF44: 24.7611 | FG44: 213.573 | FH44: 405.247 | FI44: -161.263 | FJ44: -208.769 | FK44: 148.704 | FL44: 0 | FM44: Pt10 17 modified
A45: 37 | B45: 6 | C45: 3102613 | D45: SpliceInbLH | E45: 4916010 | F45: 3916013 | G45: 3916010 | H45: 3916012 | I45: 51.48 | J45: 2_101_0 | K45: CDR_Pivot_V161_rightdown_all | L45: SUBCASE 101 = STLN ULT (INTACT) :STLN ULT (INTACT) | M45: Simulation 1 | N45: 28910.19671926622 -152.5984240114717 3875.0115942784673 | O45: 28869.6 | P45: -2216.55 | Q45: 368.389 | R45: 34305.2 | S45: 28944.62220421529 -152.31646669770896 3886.839598594263 | T45: 28940.103121184922 -152.42924962321405 3877.5890426879214 | U45: 28935.584038154553 -152.54203254871916 3868.3384867815803 | V45: 28931.064955124184 -152.65481547422425 3859.087930875239 | W45: 28926.545872093815 -152.76759839972937 3849.837374968898 | X45: 28922.026789063446 -152.88038132523445 3840.5868190625565 | Y45: 28912.775678114187 -152.88038132523445 3845.1061732425796 | Z45: 28903.524567164928 -152.88038132523445 3849.6255274226028 | AA45: 28894.273456215666 -152.88038132523445 3854.1448816026254 | AB45: 28885.022345266407 -152.88038132523445 3858.6642357826486 | AC45: 28875.771234317148 -152.88038132523445 3863.1835899626717 | AD45: 28880.290317347517 -152.76759839972937 3872.4341458690133 | AE45: 28884.809400377886 -152.65481547422425 3881.6847017753544 | AF45: 28889.328483408255 -152.54203254871916 3890.9352576816955 | AG45: 28893.847566438624 -152.42924962321405 3900.1858135880366 | AH45: 28898.366649468993 -152.31646669770896 3909.436369494378 | AI45: 28907.617760418252 -152.31646669770896 3904.917015314355 | AJ45: 28916.86887136751 -152.31646669770896 3900.397661134332 | AK45: 28926.119982316774 -152.31646669770896 3895.878306954309 | AL45: 28935.371093266032 -152.31646669770896 3891.358952774286 | AM45: 0 | AN45: 0 | AO45: 0 | AP45: 0 | AQ45: 0 | AR45: 0 | AS45: 0 | AT45: 0 | AU45: 0 | AV45: 0 | AW45: 0 | AX45: 0 | AY45: 0 | AZ45: 0 | BA45: 0 | BB45: 0 | BC45: 0 | BD45: 0 | BE45: 0 | BF45: 0 | BG45: 0 | BH45: 0 | BI45: 0 | BJ45: 0 | BK45: 0 | BL45: 0 | BM45: 0 | BN45: 0 | BO45: 0 | BP45: 0 | BQ45: 0 | BR45: 0 | BS45: 0 | BT45: 0 | BU45: 0 | BV45: 0 | BW45: 0 | BX45: 0 | BY45: 0 | BZ45: 0 | CA45: 0 | CB45: 0 | CC45: 0 | CD45: 0 | CE45: 0 | CF45: 0 | CG45: 0 | CH45: 0 | CI45: 0 | CJ45: 0 | CK45: 0 | CL45: 0 | CM45: 0 | CN45: 0 | CO45: 0 | CP45: 0 | CQ45: 0 | CR45: 0 | CS45: 0 | CT45: 0 | CU45: 0 | CV45: 0 | CW45: 0 | CX45: 0 | CY45: 0 | CZ45: 0 | DA45: 0 | DB45: 0 | DC45: 0 | DD45: 0 | DE45: 0 | DF45: 0 | DG45: 0 | DH45: 0 | DI45: 0 | DJ45: 0 | DK45: 0 | DL45: 0 | DM45: 0 | DN45: 0 | DO45: 0 | DP45: 0 | DQ45: 0 | DR45: 0 | DS45: 0 | DT45: 0 | DU45: 0 | DV45: 0 | DW45: 0 | DX45: 0 | DY45: 0 | DZ45: 0 | EA45: 0 | EB45: 0 | EC45: 0 | ED45: 0 | EE45: 0 | EF45: 0 | EG45: 0 | EH45: 0 | EI45: 0 | EJ45: 0 | EK45: 0 | EL45: 0 | EM45: 0 | EN45: 0 | EO45: 0 | EP45: 0 | EQ45: 0 | ER45: 0 | ES45: 0 | ET45: 0 | EU45: 0 | EV45: 0 | EW45: 0 | EX45: 0 | EY45: 0 | EZ45: 0 | FA45: 0 | FB45: 0 | FC45: 0 | FD45: 0 | FE45: 0 | FF45: 0 | FG45: 0 | FH45: 0 | FI45: 0 | FJ45: 0 | FK45: 0 | FL45: 0
A46: 38 | B46: 6 | C46: 3102613 | D46: SpliceInbLH | E46: 4916010 | F46: 3916013 | G46: 3916010 | H46: 3916012 | I46: 51.48 | J46: 3_102_0 | K46: CDR_Pivot_V161_leftdown_all | L46: SUBCASE 102 = STLP ULT (INTACT) :STLP ULT (INTACT) | M46: Simulation 1 | N46: 28910.19671926622 -152.5984240114717 3875.0115942784673 | O46: -26758.4 | P46: 4247.03 | Q46: -417.541 | R46: 14200.5 | S46: 28944.62220421529 -152.31646669770896 3886.839598594263 | T46: 28940.103121184922 -152.42924962321405 3877.5890426879214 | U46: 28935.584038154553 -152.54203254871916 3868.3384867815803 | V46: 28931.064955124184 -152.65481547422425 3859.087930875239 | W46: 28926.545872093815 -152.76759839972937 3849.837374968898 | X46: 28922.026789063446 -152.88038132523445 3840.5868190625565 | Y46: 28912.775678114187 -152.88038132523445 3845.1061732425796 | Z46: 28903.524567164928 -152.88038132523445 3849.6255274226028 | AA46: 28894.273456215666 -152.88038132523445 3854.1448816026254 | AB46: 28885.022345266407 -152.88038132523445 3858.6642357826486 | AC46: 28875.771234317148 -152.88038132523445 3863.1835899626717 | AD46: 28880.290317347517 -152.76759839972937 3872.4341458690133 | AE46: 28884.809400377886 -152.65481547422425 3881.6847017753544 | AF46: 28889.328483408255 -152.54203254871916 3890.9352576816955 | AG46: 28893.847566438624 -152.42924962321405 3900.1858135880366 | AH46: 28898.366649468993 -152.31646669770896 3909.436369494378 | AI46: 28907.617760418252 -152.31646669770896 3904.917015314355 | AJ46: 28916.86887136751 -152.31646669770896 3900.397661134332 | AK46: 28926.119982316774 -152.31646669770896 3895.878306954309 | AL46: 28935.371093266032 -152.31646669770896 3891.358952774286 | AM46: 0 | AN46: 0 | AO46: 0 | AP46: 0 | AQ46: 0 | AR46: 0 | AS46: 0 | AT46: 0 | AU46: 0 | AV46: 0 | AW46: 0 | AX46: 0 | AY46: 0 | AZ46: 0 | BA46: 0 | BB46: 0 | BC46: 0 | BD46: 0 | BE46: 0 | BF46: 0 | BG46: 0 | BH46: 0 | BI46: 0 | BJ46: 0 | BK46: 0 | BL46: 0 | BM46: 0 | BN46: 0 | BO46: 0 | BP46: 0 | BQ46: 0 | BR46: 0 | BS46: 0 | BT46: 0 | BU46: 0 | BV46: 0 | BW46: 0 | BX46: 0 | BY46: 0 | BZ46: 0 | CA46: 0 | CB46: 0 | CC46: 0 | CD46: 0 | CE46: 0 | CF46: 0 | CG46: 0 | CH46: 0 | CI46: 0 | CJ46: 0 | CK46: 0 | CL46: 0 | CM46: 0 | CN46: 0 | CO46: 0 | CP46: 0 | CQ46: 0 | CR46: 0 | CS46: 0 | CT46: 0 | CU46: 0 | CV46: 0 | CW46: 0 | CX46: 0 | CY46: 0 | CZ46: 0 | DA46: 0 | DB46: 0 | DC46: 0 | DD46: 0 | DE46: 0 | DF46: 0 | DG46: 0 | DH46: 0 | DI46: 0 | DJ46: 0 | DK46: 0 | DL46: 0 | DM46: 0 | DN46: 0 | DO46: 0 | DP46: 0 | DQ46: 0 | DR46: 0 | DS46: 0 | DT46: 0 | DU46: 0 | DV46: 0 | DW46: 0 | DX46: 0 | DY46: 0 | DZ46: 0 | EA46: 0 | EB46: 0 | EC46: 0 | ED46: 0 | EE46: 0 | EF46: 0 | EG46: 0 | EH46: 0 | EI46: 0 | EJ46: 0 | EK46: 0 | EL46: 0 | EM46: 0 | EN46: 0 | EO46: 0 | EP46: 0 | EQ46: 0 | ER46: 0 | ES46: 0 | ET46: 0 | EU46: 0 | EV46: 0 | EW46: 0 | EX46: 0 | EY46: 0 | EZ46: 0 | FA46: 0 | FB46: 0 | FC46: 0 | FD46: 0 | FE46: 0 | FF46: 0 | FG46: 0 | FH46: 0 | FI46: 0 | FJ46: 0 | FK46: 0 | FL46: 0
