Workbook

Sheet input
B1: Section / Laminate number
A3: ply | B3: 1 | C3: 2 | D3: 3 | E3: 4 | F3: 5 | G3: 6 | H3: 7 | I3: 8 | J3: 9 | K3: 10 | L3: 11 | M3: 12 | N3: 13 | O3: 14 | P3: 15 | Q3: 16 | R3: 17 | S3: 18 | T3: 19 | U3: 20 | V3: 21 | W3: 22 | X3: 23 | Y3: 24 | Z3: 25 | AA3: 26 | AB3: 27 | AC3: 28 | AD3: 29 | AE3: 30 | AF3: 31 | AG3: 32 | AH3: 33 | AI3: 34 | AJ3: 35 | AK3: 36 | AL3: 37 | AM3: 38 | AN3: 39 | AO3: 40 | AP3: 41 | AQ3: 42 | AR3: 43 | AS3: 44 | AT3: 45 | AU3: 46 | AV3: 47 | AW3: 48 | AX3: 49 | AY3: 50 | AZ3: 51 | BA3: 52 | BB3: 53 | BC3: 54 | BD3: 55 | BE3: 56 | BF3: 57 | BG3: 58 | BH3: 59 | BI3: 60 | BJ3: 61 | BK3: 62 | BL3: 63 | BM3: 64 | BN3: 65 | BO3: 66 | BP3: 67 | BQ3: 68 | BR3: 69 | BS3: 70 | BT3: 71 | BU3: 72 | BV3: 73 | BW3: 74 | BX3: 75 | BY3: 76 | BZ3: 77 | CA3: 78 | CB3: 79 | CC3: 80 | CD3: 81 | CE3: 82 | CF3: 83 | CG3: 84 | CH3: 85 | CI3: 86 | CJ3: 87 | CK3: 88 | CL3: 89 | CM3: 90 | CN3: 91 | CO3: 92 | CP3: 93 | CQ3: 94 | CR3: 95 | CS3: 96 | CT3: 97 | CU3: 98 | CV3: 99 | CW3: 100
A4: 1 | B4: 45 | C4: 45 | D4: 45
A5: 2 | B5: -45 | C5: -45 | D5: -45
A6: 3 | B6: 90 | C6: 90 | D6: 90
A7: 4 | B7: 0 | D7: 0
A8: 5 | B8: 0 | D8: 0
A9: 6 | B9: -45
A10: 7 | B10: 45
A11: 8 | B11: 90
A12: 9 | B12: 0
A13: 10 | B13: 0
A14: 11 | B14: 90
A15: 12 | B15: 45 | C15: -45
A16: 13 | B16: -45 | C16: 45
A17: 14 | B17: 0
A18: 15 | B18: 0 | C18: 0 | D18: 0
A19: 16 | B19: 90
A20: 17 | B20: -45 | C20: -45
A21: 18 | B21: 45 | C21: 45
A22: 19 | B22: 0
A23: 20 | B23: 0
A24: 21 | B24: 90
A25: 22 | B25: 45
A26: 23 | B26: -45
A27: 24 | B27: 0 | D27: 0
A28: 25 | B28: 0 | D28: 0
A29: 26 | B29: 90 | C29: 90 | D29: 90
A30: 27 | B30: -45 | C30: -45 | D30: -45
A31: 28 | B31: 45 | C31: 45 | D31: 45
A32: 29
A33: 30
A34: 31
A35: 32
A36: 33
A37: 34
A38: 35
A39: 36
A40: 37
A41: 38
...

Sheet aux
B1: Section / Laminate number
A3: ply | B3: 1 | C3: 2 | D3: 3 | E3: 4 | F3: 5 | G3: 6 | H3: 7 | I3: 8 | J3: 9 | K3: 10 | L3: 11 | M3: 12 | N3: 13 | O3: 14 | P3: 15 | Q3: 16 | R3: 17 | S3: 18 | T3: 19 | U3: 20 | V3: 21 | W3: 22 | X3: 23 | Y3: 24 | Z3: 25 | AA3: 26
A4: 1 | B4: =IF(input!B4="",NA(),input!B4) -> 45 | C4: =IF(input!C4="",NA(),input!C4) -> 45 | D4: =IF(input!D4="",NA(),input!D4) -> 45 | E4: =IF(input!E4="",NA(),input!E4) -> #N/A | F4: =IF(input!F4="",NA(),input!F4) -> #N/A | G4: =IF(input!G4="",NA(),input!G4) -> #N/A | H4: =IF(input!H4="",NA(),input!H4) -> #N/A | I4: =IF(input!I4="",NA(),input!I4) -> #N/A | ... CW4: =IF(input!CW4="",NA(),input!CW4) -> #N/A
A5: 2 | B5: =IF(input!B5="",NA(),input!B5) -> -45 | C5: =IF(input!C5="",NA(),input!C5) -> -45 | D5: =IF(input!D5="",NA(),input!D5) -> -45 | E5: =IF(input!E5="",NA(),input!E5) -> #N/A | F5: =IF(input!F5="",NA(),input!F5) -> #N/A | G5: =IF(input!G5="",NA(),input!G5) -> #N/A | H5: =IF(input!H5="",NA(),input!H5) -> #N/A | I5: =IF(input!I5="",NA(),input!I5) -> #N/A | ... CW5: =IF(input!CW5="",NA(),input!CW5) -> #N/A
A6: 3 | B6: =IF(input!B6="",NA(),input!B6) -> 90 | C6: =IF(input!C6="",NA(),input!C6) -> 90 | D6: =IF(input!D6="",NA(),input!D6) -> 90 | E6: =IF(input!E6="",NA(),input!E6) -> #N/A | F6: =IF(input!F6="",NA(),input!F6) -> #N/A | G6: =IF(input!G6="",NA(),input!G6) -> #N/A | H6: =IF(input!H6="",NA(),input!H6) -> #N/A | I6: =IF(input!I6="",NA(),input!I6) -> #N/A | ... CW6: =IF(input!CW6="",NA(),input!CW6) -> #N/A
A7: 4 | B7: =IF(input!B7="",NA(),input!B7) -> 0 | C7: =IF(input!C7="",NA(),input!C7) -> #N/A | D7: =IF(input!D7="",NA(),input!D7) -> 0 | E7: =IF(input!E7="",NA(),input!E7) -> #N/A | F7: =IF(input!F7="",NA(),input!F7) -> #N/A | G7: =IF(input!G7="",NA(),input!G7) -> #N/A | H7: =IF(input!H7="",NA(),input!H7) -> #N/A | I7: =IF(input!I7="",NA(),input!I7) -> #N/A | ... CW7: =IF(input!CW7="",NA(),input!CW7) -> #N/A
A8: 5 | B8: =IF(input!B8="",NA(),input!B8) -> 0 | C8: =IF(input!C8="",NA(),input!C8) -> #N/A | D8: =IF(input!D8="",NA(),input!D8) -> 0 | E8: =IF(input!E8="",NA(),input!E8) -> #N/A | F8: =IF(input!F8="",NA(),input!F8) -> #N/A | G8: =IF(input!G8="",NA(),input!G8) -> #N/A | H8: =IF(input!H8="",NA(),input!H8) -> #N/A | I8: =IF(input!I8="",NA(),input!I8) -> #N/A | ... CW8: =IF(input!CW8="",NA(),input!CW8) -> #N/A
A9: 6 | B9: =IF(input!B9="",NA(),input!B9) -> -45 | C9: =IF(input!C9="",NA(),input!C9) -> #N/A | D9: =IF(input!D9="",NA(),input!D9) -> #N/A | E9: =IF(input!E9="",NA(),input!E9) -> #N/A | F9: =IF(input!F9="",NA(),input!F9) -> #N/A | G9: =IF(input!G9="",NA(),input!G9) -> #N/A | H9: =IF(input!H9="",NA(),input!H9) -> #N/A | I9: =IF(input!I9="",NA(),input!I9) -> #N/A | ... CW9: =IF(input!CW9="",NA(),input!CW9) -> #N/A
A10: 7 | B10: =IF(input!B10="",NA(),input!B10) -> 45 | C10: =IF(input!C10="",NA(),input!C10) -> #N/A | D10: =IF(input!D10="",NA(),input!D10) -> #N/A | E10: =IF(input!E10="",NA(),input!E10) -> #N/A | F10: =IF(input!F10="",NA(),input!F10) -> #N/A | G10: =IF(input!G10="",NA(),input!G10) -> #N/A | H10: =IF(input!H10="",NA(),input!H10) -> #N/A | I10: =IF(input!I10="",NA(),input!I10) -> #N/A | ... CW10: =IF(input!CW10="",NA(),input!CW10) -> #N/A
A11: 8 | B11: =IF(input!B11="",NA(),input!B11) -> 90 | C11: =IF(input!C11="",NA(),input!C11) -> #N/A | D11: =IF(input!D11="",NA(),input!D11) -> #N/A | E11: =IF(input!E11="",NA(),input!E11) -> #N/A | F11: =IF(input!F11="",NA(),input!F11) -> #N/A | G11: =IF(input!G11="",NA(),input!G11) -> #N/A | H11: =IF(input!H11="",NA(),input!H11) -> #N/A | I11: =IF(input!I11="",NA(),input!I11) -> #N/A | ... CW11: =IF(input!CW11="",NA(),input!CW11) -> #N/A
A12: 9 | B12: =IF(input!B12="",NA(),input!B12) -> 0 | C12: =IF(input!C12="",NA(),input!C12) -> #N/A | D12: =IF(input!D12="",NA(),input!D12) -> #N/A | E12: =IF(input!E12="",NA(),input!E12) -> #N/A | F12: =IF(input!F12="",NA(),input!F12) -> #N/A | G12: =IF(input!G12="",NA(),input!G12) -> #N/A | H12: =IF(input!H12="",NA(),input!H12) -> #N/A | I12: =IF(input!I12="",NA(),input!I12) -> #N/A | ... CW12: =IF(input!CW12="",NA(),input!CW12) -> #N/A
A13: 10 | B13: =IF(input!B13="",NA(),input!B13) -> 0 | C13: =IF(input!C13="",NA(),input!C13) -> #N/A | D13: =IF(input!D13="",NA(),input!D13) -> #N/A | E13: =IF(input!E13="",NA(),input!E13) -> #N/A | F13: =IF(input!F13="",NA(),input!F13) -> #N/A | G13: =IF(input!G13="",NA(),input!G13) -> #N/A | H13: =IF(input!H13="",NA(),input!H13) -> #N/A | I13: =IF(input!I13="",NA(),input!I13) -> #N/A | ... CW13: =IF(input!CW13="",NA(),input!CW13) -> #N/A
A14: 11 | B14: =IF(input!B14="",NA(),input!B14) -> 90 | C14: =IF(input!C14="",NA(),input!C14) -> #N/A | D14: =IF(input!D14="",NA(),input!D14) -> #N/A | E14: =IF(input!E14="",NA(),input!E14) -> #N/A | F14: =IF(input!F14="",NA(),input!F14) -> #N/A | G14: =IF(input!G14="",NA(),input!G14) -> #N/A | H14: =IF(input!H14="",NA(),input!H14) -> #N/A | I14: =IF(input!I14="",NA(),input!I14) -> #N/A | ... CW14: =IF(input!CW14="",NA(),input!CW14) -> #N/A
A15: 12 | B15: =IF(input!B15="",NA(),input!B15) -> 45 | C15: =IF(input!C15="",NA(),input!C15) -> -45 | D15: =IF(input!D15="",NA(),input!D15) -> #N/A | E15: =IF(input!E15="",NA(),input!E15) -> #N/A | F15: =IF(input!F15="",NA(),input!F15) -> #N/A | G15: =IF(input!G15="",NA(),input!G15) -> #N/A | H15: =IF(input!H15="",NA(),input!H15) -> #N/A | I15: =IF(input!I15="",NA(),input!I15) -> #N/A | ... CW15: =IF(input!CW15="",NA(),input!CW15) -> #N/A
... A103: 100 | B103: =IF(input!B103="",NA(),input!B103) -> #N/A | C103: =IF(input!C103="",NA(),input!C103) -> #N/A | D103: =IF(input!D103="",NA(),input!D103) -> #N/A | E103: =IF(input!E103="",NA(),input!E103) -> #N/A | F103: =IF(input!F103="",NA(),input!F103) -> #N/A | G103: =IF(input!G103="",NA(),input!G103) -> #N/A | H103: =IF(input!H103="",NA(),input!H103) -> #N/A | I103: =IF(input!I103="",NA(),input!I103) -> #N/A | ... CW103: =IF(input!CW103="",NA(),input!CW103) -> #N/A

Sheet transpose
B1: Plys number
B3: 1 | C3: 2 | D3: 3 | E3: 4 | F3: 5 | G3: 6 | H3: 7 | I3: 8 | J3: 9 | K3: 10 | L3: 11 | M3: 12 | N3: 13 | O3: 14 | P3: 15 | Q3: 16 | R3: 17 | S3: 18 | T3: 19 | U3: 20 | V3: 21 | W3: 22 | X3: 23 | Y3: 24 | Z3: 25 | AA3: 26 | AB3: 27 | AC3: 28 | AD3: 29 | AE3: 30 | AF3: 31 | AG3: 32 | AH3: 33 | AI3: 34 | AJ3: 35 | AK3: 36 | AL3: 37 | AM3: 38 | AN3: 39 | AO3: 40 | AP3: 41 | AQ3: 42 | AR3: 43 | AS3: 44 | AT3: 45 | AU3: 46 | AV3: 47 | AW3: 48 | AX3: 49 | AY3: 50 | AZ3: 51 | BA3: 52 | BB3: 53 | BC3: 54 | BD3: 55 | BE3: 56 | BF3: 57 | BG3: 58 | BH3: 59 | BI3: 60 | BJ3: 61 | BK3: 62 | BL3: 63 | BM3: 64 | BN3: 65 | BO3: 66 | BP3: 67 | BQ3: 68 | BR3: 69 | BS3: 70 | BT3: 71 | BU3: 72 | BV3: 73 | BW3: 74 | BX3: 75 | BY3: 76 | BZ3: 77 | CA3: 78 | CB3: 79 | CC3: 80 | CD3: 81 | CE3: 82 | CF3: 83 | CG3: 84 | CH3: 85 | CI3: 86 | CJ3: 87 | CK3: 88 | CL3: 89 | CM3: 90 | CN3: 91 | CO3: 92 | CP3: 93 | CQ3: 94 | CR3: 95 | CS3: 96 | CT3: 97 | CU3: 98 | CV3: 99 | CW3: 100
B4: {=TRANSPOSE(aux!B4:CW103)} -> 45 | C4: -45 | D4: 90 | E4: 0 | F4: 0 | G4: -45 | H4: 45 | I4: 90 | J4: 0 | K4: 0 | L4: 90 | M4: 45 | N4: -45 | O4: 0 | P4: 0 | Q4: 90 | R4: -45 | S4: 45 | T4: 0 | U4: 0 | V4: 90 | W4: 45 | X4: -45 | Y4: 0 | Z4: 0 | AA4: 90 | AB4: -45 | AC4: 45 | AD4: #N/A | AE4: #N/A | AF4: #N/A | AG4: #N/A | AH4: #N/A | AI4: #N/A | AJ4: #N/A | AK4: #N/A | AL4: #N/A | AM4: #N/A | AN4: #N/A | AO4: #N/A | AP4: #N/A | AQ4: #N/A | AR4: #N/A | AS4: #N/A | AT4: #N/A | AU4: #N/A | AV4: #N/A | AW4: #N/A | AX4: #N/A | AY4: #N/A | AZ4: #N/A | BA4: #N/A | BB4: #N/A | BC4: #N/A | BD4: #N/A | BE4: #N/A | BF4: #N/A | BG4: #N/A | BH4: #N/A | BI4: #N/A | BJ4: #N/A | BK4: #N/A | BL4: #N/A | BM4: #N/A | BN4: #N/A | BO4: #N/A | BP4: #N/A | BQ4: #N/A | BR4: #N/A | BS4: #N/A | BT4: #N/A | BU4: #N/A | BV4: #N/A | BW4: #N/A | BX4: #N/A | BY4: #N/A | BZ4: #N/A | CA4: #N/A | CB4: #N/A | CC4: #N/A | CD4: #N/A | CE4: #N/A | CF4: #N/A | CG4: #N/A | CH4: #N/A | CI4: #N/A | CJ4: #N/A | CK4: #N/A | CL4: #N/A | CM4: #N/A | CN4: #N/A | CO4: #N/A | CP4: #N/A | CQ4: #N/A | CR4: #N/A | CS4: #N/A | CT4: #N/A | CU4: #N/A | CV4: #N/A | CW4: #N/A
B5: 45 | C5: -45 | D5: 90 | E5: #N/A | F5: #N/A | G5: #N/A | H5: #N/A | I5: #N/A | J5: #N/A | K5: #N/A | L5: #N/A | M5: -45 | N5: 45 | O5: #N/A | P5: 0 | Q5: #N/A | R5: -45 | S5: 45 | T5: #N/A | U5: #N/A | V5: #N/A | W5: #N/A | X5: #N/A | Y5: #N/A | Z5: #N/A | AA5: 90 | AB5: -45 | AC5: 45 | AD5: #N/A | AE5: #N/A | AF5: #N/A | AG5: #N/A | AH5: #N/A | AI5: #N/A | AJ5: #N/A | AK5: #N/A | AL5: #N/A | AM5: #N/A | AN5: #N/A | AO5: #N/A | AP5: #N/A | AQ5: #N/A | AR5: #N/A | AS5: #N/A | AT5: #N/A | AU5: #N/A | AV5: #N/A | AW5: #N/A | AX5: #N/A | AY5: #N/A | AZ5: #N/A | BA5: #N/A | BB5: #N/A | BC5: #N/A | BD5: #N/A | BE5: #N/A | BF5: #N/A | BG5: #N/A | BH5: #N/A | BI5: #N/A | BJ5: #N/A | BK5: #N/A | BL5: #N/A | BM5: #N/A | BN5: #N/A | BO5: #N/A | BP5: #N/A | BQ5: #N/A | BR5: #N/A | BS5: #N/A | BT5: #N/A | BU5: #N/A | BV5: #N/A | BW5: #N/A | BX5: #N/A | BY5: #N/A | BZ5: #N/A | CA5: #N/A | CB5: #N/A | CC5: #N/A | CD5: #N/A | CE5: #N/A | CF5: #N/A | CG5: #N/A | CH5: #N/A | CI5: #N/A | CJ5: #N/A | CK5: #N/A | CL5: #N/A | CM5: #N/A | CN5: #N/A | CO5: #N/A | CP5: #N/A | CQ5: #N/A | CR5: #N/A | CS5: #N/A | CT5: #N/A | CU5: #N/A | CV5: #N/A | CW5: #N/A
B6: 45 | C6: -45 | D6: 90 | E6: 0 | F6: 0 | G6: #N/A | H6: #N/A | I6: #N/A | J6: #N/A | K6: #N/A | L6: #N/A | M6: #N/A | N6: #N/A | O6: #N/A | P6: 0 | Q6: #N/A | R6: #N/A | S6: #N/A | T6: #N/A | U6: #N/A | V6: #N/A | W6: #N/A | X6: #N/A | Y6: 0 | Z6: 0 | AA6: 90 | AB6: -45 | AC6: 45 | AD6: #N/A | AE6: #N/A | AF6: #N/A | AG6: #N/A | AH6: #N/A | AI6: #N/A | AJ6: #N/A | AK6: #N/A | AL6: #N/A | AM6: #N/A | AN6: #N/A | AO6: #N/A | AP6: #N/A | AQ6: #N/A | AR6: #N/A | AS6: #N/A | AT6: #N/A | AU6: #N/A | AV6: #N/A | AW6: #N/A | AX6: #N/A | AY6: #N/A | AZ6: #N/A | BA6: #N/A | BB6: #N/A | BC6: #N/A | BD6: #N/A | BE6: #N/A | BF6: #N/A | BG6: #N/A | BH6: #N/A | BI6: #N/A | BJ6: #N/A | BK6: #N/A | BL6: #N/A | BM6: #N/A | BN6: #N/A | BO6: #N/A | BP6: #N/A | BQ6: #N/A | BR6: #N/A | BS6: #N/A | BT6: #N/A | BU6: #N/A | BV6: #N/A | BW6: #N/A | BX6: #N/A | BY6: #N/A | BZ6: #N/A | CA6: #N/A | CB6: #N/A | CC6: #N/A | CD6: #N/A | CE6: #N/A | CF6: #N/A | CG6: #N/A | CH6: #N/A | CI6: #N/A | CJ6: #N/A | CK6: #N/A | CL6: #N/A | CM6: #N/A | CN6: #N/A | CO6: #N/A | CP6: #N/A | CQ6: #N/A | CR6: #N/A | CS6: #N/A | CT6: #N/A | CU6: #N/A | CV6: #N/A | CW6: #N/A
B7: #N/A | C7: #N/A | D7: #N/A | E7: #N/A | F7: #N/A | G7: #N/A | H7: #N/A | I7: #N/A | J7: #N/A | K7: #N/A | L7: #N/A | M7: #N/A | N7: #N/A | O7: #N/A | P7: #N/A | Q7: #N/A | R7: #N/A | S7: #N/A | T7: #N/A | U7: #N/A | V7: #N/A | W7: #N/A | X7: #N/A | Y7: #N/A | Z7: #N/A | AA7: #N/A | AB7: #N/A | AC7: #N/A | AD7: #N/A | AE7: #N/A | AF7: #N/A | AG7: #N/A | AH7: #N/A | AI7: #N/A | AJ7: #N/A | AK7: #N/A | AL7: #N/A | AM7: #N/A | AN7: #N/A | AO7: #N/A | AP7: #N/A | AQ7: #N/A | AR7: #N/A | AS7: #N/A | AT7: #N/A | AU7: #N/A | AV7: #N/A | AW7: #N/A | AX7: #N/A | AY7: #N/A | AZ7: #N/A | BA7: #N/A | BB7: #N/A | BC7: #N/A | BD7: #N/A | BE7: #N/A | BF7: #N/A | BG7: #N/A | BH7: #N/A | BI7: #N/A | BJ7: #N/A | BK7: #N/A | BL7: #N/A | BM7: #N/A | BN7: #N/A | BO7: #N/A | BP7: #N/A | BQ7: #N/A | BR7: #N/A | BS7: #N/A | BT7: #N/A | BU7: #N/A | BV7: #N/A | BW7: #N/A | BX7: #N/A | BY7: #N/A | BZ7: #N/A | CA7: #N/A | CB7: #N/A | CC7: #N/A | CD7: #N/A | CE7: #N/A | CF7: #N/A | CG7: #N/A | CH7: #N/A | CI7: #N/A | CJ7: #N/A | CK7: #N/A | CL7: #N/A | CM7: #N/A | CN7: #N/A | CO7: #N/A | CP7: #N/A | CQ7: #N/A | CR7: #N/A | CS7: #N/A | CT7: #N/A | CU7: #N/A | CV7: #N/A | CW7: #N/A
B8: #N/A | C8: #N/A | D8: #N/A | E8: #N/A | F8: #N/A | G8: #N/A | H8: #N/A | I8: #N/A | J8: #N/A | K8: #N/A | L8: #N/A | M8: #N/A | N8: #N/A | O8: #N/A | P8: #N/A | Q8: #N/A | R8: #N/A | S8: #N/A | T8: #N/A | U8: #N/A | V8: #N/A | W8: #N/A | X8: #N/A | Y8: #N/A | Z8: #N/A | AA8: #N/A | AB8: #N/A | AC8: #N/A | AD8: #N/A | AE8: #N/A | AF8: #N/A | AG8: #N/A | AH8: #N/A | AI8: #N/A | AJ8: #N/A | AK8: #N/A | AL8: #N/A | AM8: #N/A | AN8: #N/A | AO8: #N/A | AP8: #N/A | AQ8: #N/A | AR8: #N/A | AS8: #N/A | AT8: #N/A | AU8: #N/A | AV8: #N/A | AW8: #N/A | AX8: #N/A | AY8: #N/A | AZ8: #N/A | BA8: #N/A | BB8: #N/A | BC8: #N/A | BD8: #N/A | BE8: #N/A | BF8: #N/A | BG8: #N/A | BH8: #N/A | BI8: #N/A | BJ8: #N/A | BK8: #N/A | BL8: #N/A | BM8: #N/A | BN8: #N/A | BO8: #N/A | BP8: #N/A | BQ8: #N/A | BR8: #N/A | BS8: #N/A | BT8: #N/A | BU8: #N/A | BV8: #N/A | BW8: #N/A | BX8: #N/A | BY8: #N/A | BZ8: #N/A | CA8: #N/A | CB8: #N/A | CC8: #N/A | CD8: #N/A | CE8: #N/A | CF8: #N/A | CG8: #N/A | CH8: #N/A | CI8: #N/A | CJ8: #N/A | CK8: #N/A | CL8: #N/A | CM8: #N/A | CN8: #N/A | CO8: #N/A | CP8: #N/A | CQ8: #N/A | CR8: #N/A | CS8: #N/A | CT8: #N/A | CU8: #N/A | CV8: #N/A | CW8: #N/A
B9: #N/A | C9: #N/A | D9: #N/A | E9: #N/A | F9: #N/A | G9: #N/A | H9: #N/A | I9: #N/A | J9: #N/A | K9: #N/A | L9: #N/A | M9: #N/A | N9: #N/A | O9: #N/A | P9: #N/A | Q9: #N/A | R9: #N/A | S9: #N/A | T9: #N/A | U9: #N/A | V9: #N/A | W9: #N/A | X9: #N/A | Y9: #N/A | Z9: #N/A | AA9: #N/A | AB9: #N/A | AC9: #N/A | AD9: #N/A | AE9: #N/A | AF9: #N/A | AG9: #N/A | AH9: #N/A | AI9: #N/A | AJ9: #N/A | AK9: #N/A | AL9: #N/A | AM9: #N/A | AN9: #N/A | AO9: #N/A | AP9: #N/A | AQ9: #N/A | AR9: #N/A | AS9: #N/A | AT9: #N/A | AU9: #N/A | AV9: #N/A | AW9: #N/A | AX9: #N/A | AY9: #N/A | AZ9: #N/A | BA9: #N/A | BB9: #N/A | BC9: #N/A | BD9: #N/A | BE9: #N/A | BF9: #N/A | BG9: #N/A | BH9: #N/A | BI9: #N/A | BJ9: #N/A | BK9: #N/A | BL9: #N/A | BM9: #N/A | BN9: #N/A | BO9: #N/A | BP9: #N/A | BQ9: #N/A | BR9: #N/A | BS9: #N/A | BT9: #N/A | BU9: #N/A | BV9: #N/A | BW9: #N/A | BX9: #N/A | BY9: #N/A | BZ9: #N/A | CA9: #N/A | CB9: #N/A | CC9: #N/A | CD9: #N/A | CE9: #N/A | CF9: #N/A | CG9: #N/A | CH9: #N/A | CI9: #N/A | CJ9: #N/A | CK9: #N/A | CL9: #N/A | CM9: #N/A | CN9: #N/A | CO9: #N/A | CP9: #N/A | CQ9: #N/A | CR9: #N/A | CS9: #N/A | CT9: #N/A | CU9: #N/A | CV9: #N/A | CW9: #N/A
B10: #N/A | C10: #N/A | D10: #N/A | E10: #N/A | F10: #N/A | G10: #N/A | H10: #N/A | I10: #N/A | J10: #N/A | K10: #N/A | L10: #N/A | M10: #N/A | N10: #N/A | O10: #N/A | P10: #N/A | Q10: #N/A | R10: #N/A | S10: #N/A | T10: #N/A | U10: #N/A | V10: #N/A | W10: #N/A | X10: #N/A | Y10: #N/A | Z10: #N/A | AA10: #N/A | AB10: #N/A | AC10: #N/A | AD10: #N/A | AE10: #N/A | AF10: #N/A | AG10: #N/A | AH10: #N/A | AI10: #N/A | AJ10: #N/A | AK10: #N/A | AL10: #N/A | AM10: #N/A | AN10: #N/A | AO10: #N/A | AP10: #N/A | AQ10: #N/A | AR10: #N/A | AS10: #N/A | AT10: #N/A | AU10: #N/A | AV10: #N/A | AW10: #N/A | AX10: #N/A | AY10: #N/A | AZ10: #N/A | BA10: #N/A | BB10: #N/A | BC10: #N/A | BD10: #N/A | BE10: #N/A | BF10: #N/A | BG10: #N/A | BH10: #N/A | BI10: #N/A | BJ10: #N/A | BK10: #N/A | BL10: #N/A | BM10: #N/A | BN10: #N/A | BO10: #N/A | BP10: #N/A | BQ10: #N/A | BR10: #N/A | BS10: #N/A | BT10: #N/A | BU10: #N/A | BV10: #N/A | BW10: #N/A | BX10: #N/A | BY10: #N/A | BZ10: #N/A | CA10: #N/A | CB10: #N/A | CC10: #N/A | CD10: #N/A | CE10: #N/A | CF10: #N/A | CG10: #N/A | CH10: #N/A | CI10: #N/A | CJ10: #N/A | CK10: #N/A | CL10: #N/A | CM10: #N/A | CN10: #N/A | CO10: #N/A | CP10: #N/A | CQ10: #N/A | CR10: #N/A | CS10: #N/A | CT10: #N/A | CU10: #N/A | CV10: #N/A | CW10: #N/A
B11: #N/A | C11: #N/A | D11: #N/A | E11: #N/A | F11: #N/A | G11: #N/A | H11: #N/A | I11: #N/A | J11: #N/A | K11: #N/A | L11: #N/A | M11: #N/A | N11: #N/A | O11: #N/A | P11: #N/A | Q11: #N/A | R11: #N/A | S11: #N/A | T11: #N/A | U11: #N/A | V11: #N/A | W11: #N/A | X11: #N/A | Y11: #N/A | Z11: #N/A | AA11: #N/A | AB11: #N/A | AC11: #N/A | AD11: #N/A | AE11: #N/A | AF11: #N/A | AG11: #N/A | AH11: #N/A | AI11: #N/A | AJ11: #N/A | AK11: #N/A | AL11: #N/A | AM11: #N/A | AN11: #N/A | AO11: #N/A | AP11: #N/A | AQ11: #N/A | AR11: #N/A | AS11: #N/A | AT11: #N/A | AU11: #N/A | AV11: #N/A | AW11: #N/A | AX11: #N/A | AY11: #N/A | AZ11: #N/A | BA11: #N/A | BB11: #N/A | BC11: #N/A | BD11: #N/A | BE11: #N/A | BF11: #N/A | BG11: #N/A | BH11: #N/A | BI11: #N/A | BJ11: #N/A | BK11: #N/A | BL11: #N/A | BM11: #N/A | BN11: #N/A | BO11: #N/A | BP11: #N/A | BQ11: #N/A | BR11: #N/A | BS11: #N/A | BT11: #N/A | BU11: #N/A | BV11: #N/A | BW11: #N/A | BX11: #N/A | BY11: #N/A | BZ11: #N/A | CA11: #N/A | CB11: #N/A | CC11: #N/A | CD11: #N/A | CE11: #N/A | CF11: #N/A | CG11: #N/A | CH11: #N/A | CI11: #N/A | CJ11: #N/A | CK11: #N/A | CL11: #N/A | CM11: #N/A | CN11: #N/A | CO11: #N/A | CP11: #N/A | CQ11: #N/A | CR11: #N/A | CS11: #N/A | CT11: #N/A | CU11: #N/A | CV11: #N/A | CW11: #N/A
B12: #N/A | C12: #N/A | D12: #N/A | E12: #N/A | F12: #N/A | G12: #N/A | H12: #N/A | I12: #N/A | J12: #N/A | K12: #N/A | L12: #N/A | M12: #N/A | N12: #N/A | O12: #N/A | P12: #N/A | Q12: #N/A | R12: #N/A | S12: #N/A | T12: #N/A | U12: #N/A | V12: #N/A | W12: #N/A | X12: #N/A | Y12: #N/A | Z12: #N/A | AA12: #N/A | AB12: #N/A | AC12: #N/A | AD12: #N/A | AE12: #N/A | AF12: #N/A | AG12: #N/A | AH12: #N/A | AI12: #N/A | AJ12: #N/A | AK12: #N/A | AL12: #N/A | AM12: #N/A | AN12: #N/A | AO12: #N/A | AP12: #N/A | AQ12: #N/A | AR12: #N/A | AS12: #N/A | AT12: #N/A | AU12: #N/A | AV12: #N/A | AW12: #N/A | AX12: #N/A | AY12: #N/A | AZ12: #N/A | BA12: #N/A | BB12: #N/A | BC12: #N/A | BD12: #N/A | BE12: #N/A | BF12: #N/A | BG12: #N/A | BH12: #N/A | BI12: #N/A | BJ12: #N/A | BK12: #N/A | BL12: #N/A | BM12: #N/A | BN12: #N/A | BO12: #N/A | BP12: #N/A | BQ12: #N/A | BR12: #N/A | BS12: #N/A | BT12: #N/A | BU12: #N/A | BV12: #N/A | BW12: #N/A | BX12: #N/A | BY12: #N/A | BZ12: #N/A | CA12: #N/A | CB12: #N/A | CC12: #N/A | CD12: #N/A | CE12: #N/A | CF12: #N/A | CG12: #N/A | CH12: #N/A | CI12: #N/A | CJ12: #N/A | CK12: #N/A | CL12: #N/A | CM12: #N/A | CN12: #N/A | CO12: #N/A | CP12: #N/A | CQ12: #N/A | CR12: #N/A | CS12: #N/A | CT12: #N/A | CU12: #N/A | CV12: #N/A | CW12: #N/A
B13: #N/A | C13: #N/A | D13: #N/A | E13: #N/A | F13: #N/A | G13: #N/A | H13: #N/A | I13: #N/A | J13: #N/A | K13: #N/A | L13: #N/A | M13: #N/A | N13: #N/A | O13: #N/A | P13: #N/A | Q13: #N/A | R13: #N/A | S13: #N/A | T13: #N/A | U13: #N/A | V13: #N/A | W13: #N/A | X13: #N/A | Y13: #N/A | Z13: #N/A | AA13: #N/A | AB13: #N/A | AC13: #N/A | AD13: #N/A | AE13: #N/A | AF13: #N/A | AG13: #N/A | AH13: #N/A | AI13: #N/A | AJ13: #N/A | AK13: #N/A | AL13: #N/A | AM13: #N/A | AN13: #N/A | AO13: #N/A | AP13: #N/A | AQ13: #N/A | AR13: #N/A | AS13: #N/A | AT13: #N/A | AU13: #N/A | AV13: #N/A | AW13: #N/A | AX13: #N/A | AY13: #N/A | AZ13: #N/A | BA13: #N/A | BB13: #N/A | BC13: #N/A | BD13: #N/A | BE13: #N/A | BF13: #N/A | BG13: #N/A | BH13: #N/A | BI13: #N/A | BJ13: #N/A | BK13: #N/A | BL13: #N/A | BM13: #N/A | BN13: #N/A | BO13: #N/A | BP13: #N/A | BQ13: #N/A | BR13: #N/A | BS13: #N/A | BT13: #N/A | BU13: #N/A | BV13: #N/A | BW13: #N/A | BX13: #N/A | BY13: #N/A | BZ13: #N/A | CA13: #N/A | CB13: #N/A | CC13: #N/A | CD13: #N/A | CE13: #N/A | CF13: #N/A | CG13: #N/A | CH13: #N/A | CI13: #N/A | CJ13: #N/A | CK13: #N/A | CL13: #N/A | CM13: #N/A | CN13: #N/A | CO13: #N/A | CP13: #N/A | CQ13: #N/A | CR13: #N/A | CS13: #N/A | CT13: #N/A | CU13: #N/A | CV13: #N/A | CW13: #N/A
B14: #N/A | C14: #N/A | D14: #N/A | E14: #N/A | F14: #N/A | G14: #N/A | H14: #N/A | I14: #N/A | J14: #N/A | K14: #N/A | L14: #N/A | M14: #N/A | N14: #N/A | O14: #N/A | P14: #N/A | Q14: #N/A | R14: #N/A | S14: #N/A | T14: #N/A | U14: #N/A | V14: #N/A | W14: #N/A | X14: #N/A | Y14: #N/A | Z14: #N/A | AA14: #N/A | AB14: #N/A | AC14: #N/A | AD14: #N/A | AE14: #N/A | AF14: #N/A | AG14: #N/A | AH14: #N/A | AI14: #N/A | AJ14: #N/A | AK14: #N/A | AL14: #N/A | AM14: #N/A | AN14: #N/A | AO14: #N/A | AP14: #N/A | AQ14: #N/A | AR14: #N/A | AS14: #N/A | AT14: #N/A | AU14: #N/A | AV14: #N/A | AW14: #N/A | AX14: #N/A | AY14: #N/A | AZ14: #N/A | BA14: #N/A | BB14: #N/A | BC14: #N/A | BD14: #N/A | BE14: #N/A | BF14: #N/A | BG14: #N/A | BH14: #N/A | BI14: #N/A | BJ14: #N/A | BK14: #N/A | BL14: #N/A | BM14: #N/A | BN14: #N/A | BO14: #N/A | BP14: #N/A | BQ14: #N/A | BR14: #N/A | BS14: #N/A | BT14: #N/A | BU14: #N/A | BV14: #N/A | BW14: #N/A | BX14: #N/A | BY14: #N/A | BZ14: #N/A | CA14: #N/A | CB14: #N/A | CC14: #N/A | CD14: #N/A | CE14: #N/A | CF14: #N/A | CG14: #N/A | CH14: #N/A | CI14: #N/A | CJ14: #N/A | CK14: #N/A | CL14: #N/A | CM14: #N/A | CN14: #N/A | CO14: #N/A | CP14: #N/A | CQ14: #N/A | CR14: #N/A | CS14: #N/A | CT14: #N/A | CU14: #N/A | CV14: #N/A | CW14: #N/A
B15: #N/A | C15: #N/A | D15: #N/A | E15: #N/A | F15: #N/A | G15: #N/A | H15: #N/A | I15: #N/A | J15: #N/A | K15: #N/A | L15: #N/A | M15: #N/A | N15: #N/A | O15: #N/A | P15: #N/A | Q15: #N/A | R15: #N/A | S15: #N/A | T15: #N/A | U15: #N/A | V15: #N/A | W15: #N/A | X15: #N/A | Y15: #N/A | Z15: #N/A | AA15: #N/A | AB15: #N/A | AC15: #N/A | AD15: #N/A | AE15: #N/A | AF15: #N/A | AG15: #N/A | AH15: #N/A | AI15: #N/A | AJ15: #N/A | AK15: #N/A | AL15: #N/A | AM15: #N/A | AN15: #N/A | AO15: #N/A | AP15: #N/A | AQ15: #N/A | AR15: #N/A | AS15: #N/A | AT15: #N/A | AU15: #N/A | AV15: #N/A | AW15: #N/A | AX15: #N/A | AY15: #N/A | AZ15: #N/A | BA15: #N/A | BB15: #N/A | BC15: #N/A | BD15: #N/A | BE15: #N/A | BF15: #N/A | BG15: #N/A | BH15: #N/A | BI15: #N/A | BJ15: #N/A | BK15: #N/A | BL15: #N/A | BM15: #N/A | BN15: #N/A | BO15: #N/A | BP15: #N/A | BQ15: #N/A | BR15: #N/A | BS15: #N/A | BT15: #N/A | BU15: #N/A | BV15: #N/A | BW15: #N/A | BX15: #N/A | BY15: #N/A | BZ15: #N/A | CA15: #N/A | CB15: #N/A | CC15: #N/A | CD15: #N/A | CE15: #N/A | CF15: #N/A | CG15: #N/A | CH15: #N/A | CI15: #N/A | CJ15: #N/A | CK15: #N/A | CL15: #N/A | CM15: #N/A | CN15: #N/A | CO15: #N/A | CP15: #N/A | CQ15: #N/A | CR15: #N/A | CS15: #N/A | CT15: #N/A | CU15: #N/A | CV15: #N/A | CW15: #N/A
B16: #N/A | C16: #N/A | D16: #N/A | E16: #N/A | F16: #N/A | G16: #N/A | H16: #N/A | I16: #N/A | J16: #N/A | K16: #N/A | L16: #N/A | M16: #N/A | N16: #N/A | O16: #N/A | P16: #N/A | Q16: #N/A | R16: #N/A | S16: #N/A | T16: #N/A | U16: #N/A | V16: #N/A | W16: #N/A | X16: #N/A | Y16: #N/A | Z16: #N/A | AA16: #N/A | AB16: #N/A | AC16: #N/A | AD16: #N/A | AE16: #N/A | AF16: #N/A | AG16: #N/A | AH16: #N/A | AI16: #N/A | AJ16: #N/A | AK16: #N/A | AL16: #N/A | AM16: #N/A | AN16: #N/A | AO16: #N/A | AP16: #N/A | AQ16: #N/A | AR16: #N/A | AS16: #N/A | AT16: #N/A | AU16: #N/A | AV16: #N/A | AW16: #N/A | AX16: #N/A | AY16: #N/A | AZ16: #N/A | BA16: #N/A | BB16: #N/A | BC16: #N/A | BD16: #N/A | BE16: #N/A | BF16: #N/A | BG16: #N/A | BH16: #N/A | BI16: #N/A | BJ16: #N/A | BK16: #N/A | BL16: #N/A | BM16: #N/A | BN16: #N/A | BO16: #N/A | BP16: #N/A | BQ16: #N/A | BR16: #N/A | BS16: #N/A | BT16: #N/A | BU16: #N/A | BV16: #N/A | BW16: #N/A | BX16: #N/A | BY16: #N/A | BZ16: #N/A | CA16: #N/A | CB16: #N/A | CC16: #N/A | CD16: #N/A | CE16: #N/A | CF16: #N/A | CG16: #N/A | CH16: #N/A | CI16: #N/A | CJ16: #N/A | CK16: #N/A | CL16: #N/A | CM16: #N/A | CN16: #N/A | CO16: #N/A | CP16: #N/A | CQ16: #N/A | CR16: #N/A | CS16: #N/A | CT16: #N/A | CU16: #N/A | CV16: #N/A | CW16: #N/A
B17: #N/A | C17: #N/A | D17: #N/A | E17: #N/A | F17: #N/A | G17: #N/A | H17: #N/A | I17: #N/A | J17: #N/A | K17: #N/A | L17: #N/A | M17: #N/A | N17: #N/A | O17: #N/A | P17: #N/A | Q17: #N/A | R17: #N/A | S17: #N/A | T17: #N/A | U17: #N/A | V17: #N/A | W17: #N/A | X17: #N/A | Y17: #N/A | Z17: #N/A | AA17: #N/A | AB17: #N/A | AC17: #N/A | AD17: #N/A | AE17: #N/A | AF17: #N/A | AG17: #N/A | AH17: #N/A | AI17: #N/A | AJ17: #N/A | AK17: #N/A | AL17: #N/A | AM17: #N/A | AN17: #N/A | AO17: #N/A | AP17: #N/A | AQ17: #N/A | AR17: #N/A | AS17: #N/A | AT17: #N/A | AU17: #N/A | AV17: #N/A | AW17: #N/A | AX17: #N/A | AY17: #N/A | AZ17: #N/A | BA17: #N/A | BB17: #N/A | BC17: #N/A | BD17: #N/A | BE17: #N/A | BF17: #N/A | BG17: #N/A | BH17: #N/A | BI17: #N/A | BJ17: #N/A | BK17: #N/A | BL17: #N/A | BM17: #N/A | BN17: #N/A | BO17: #N/A | BP17: #N/A | BQ17: #N/A | BR17: #N/A | BS17: #N/A | BT17: #N/A | BU17: #N/A | BV17: #N/A | BW17: #N/A | BX17: #N/A | BY17: #N/A | BZ17: #N/A | CA17: #N/A | CB17: #N/A | CC17: #N/A | CD17: #N/A | CE17: #N/A | CF17: #N/A | CG17: #N/A | CH17: #N/A | CI17: #N/A | CJ17: #N/A | CK17: #N/A | CL17: #N/A | CM17: #N/A | CN17: #N/A | CO17: #N/A | CP17: #N/A | CQ17: #N/A | CR17: #N/A | CS17: #N/A | CT17: #N/A | CU17: #N/A | CV17: #N/A | CW17: #N/A
B18: #N/A | C18: #N/A | D18: #N/A | E18: #N/A | F18: #N/A | G18: #N/A | H18: #N/A | I18: #N/A | J18: #N/A | K18: #N/A | L18: #N/A | M18: #N/A | N18: #N/A | O18: #N/A | P18: #N/A | Q18: #N/A | R18: #N/A | S18: #N/A | T18: #N/A | U18: #N/A | V18: #N/A | W18: #N/A | X18: #N/A | Y18: #N/A | Z18: #N/A | AA18: #N/A | AB18: #N/A | AC18: #N/A | AD18: #N/A | AE18: #N/A | AF18: #N/A | AG18: #N/A | AH18: #N/A | AI18: #N/A | AJ18: #N/A | AK18: #N/A | AL18: #N/A | AM18: #N/A | AN18: #N/A | AO18: #N/A | AP18: #N/A | AQ18: #N/A | AR18: #N/A | AS18: #N/A | AT18: #N/A | AU18: #N/A | AV18: #N/A | AW18: #N/A | AX18: #N/A | AY18: #N/A | AZ18: #N/A | BA18: #N/A | BB18: #N/A | BC18: #N/A | BD18: #N/A | BE18: #N/A | BF18: #N/A | BG18: #N/A | BH18: #N/A | BI18: #N/A | BJ18: #N/A | BK18: #N/A | BL18: #N/A | BM18: #N/A | BN18: #N/A | BO18: #N/A | BP18: #N/A | BQ18: #N/A | BR18: #N/A | BS18: #N/A | BT18: #N/A | BU18: #N/A | BV18: #N/A | BW18: #N/A | BX18: #N/A | BY18: #N/A | BZ18: #N/A | CA18: #N/A | CB18: #N/A | CC18: #N/A | CD18: #N/A | CE18: #N/A | CF18: #N/A | CG18: #N/A | CH18: #N/A | CI18: #N/A | CJ18: #N/A | CK18: #N/A | CL18: #N/A | CM18: #N/A | CN18: #N/A | CO18: #N/A | CP18: #N/A | CQ18: #N/A | CR18: #N/A | CS18: #N/A | CT18: #N/A | CU18: #N/A | CV18: #N/A | CW18: #N/A
... B103: #N/A | C103: #N/A | D103: #N/A | E103: #N/A | F103: #N/A | G103: #N/A | H103: #N/A | I103: #N/A | J103: #N/A | K103: #N/A | L103: #N/A | M103: #N/A | N103: #N/A | O103: #N/A | P103: #N/A | Q103: #N/A | R103: #N/A | S103: #N/A | T103: #N/A | U103: #N/A | V103: #N/A | W103: #N/A | X103: #N/A | Y103: #N/A | Z103: #N/A | AA103: #N/A | AB103: #N/A | AC103: #N/A | AD103: #N/A | AE103: #N/A | AF103: #N/A | AG103: #N/A | AH103: #N/A | AI103: #N/A | AJ103: #N/A | AK103: #N/A | AL103: #N/A | AM103: #N/A | AN103: #N/A | AO103: #N/A | AP103: #N/A | AQ103: #N/A | AR103: #N/A | AS103: #N/A | AT103: #N/A | AU103: #N/A | AV103: #N/A | AW103: #N/A | AX103: #N/A | AY103: #N/A | AZ103: #N/A | BA103: #N/A | BB103: #N/A | BC103: #N/A | BD103: #N/A | BE103: #N/A | BF103: #N/A | BG103: #N/A | BH103: #N/A | BI103: #N/A | BJ103: #N/A | BK103: #N/A | BL103: #N/A | BM103: #N/A | BN103: #N/A | BO103: #N/A | BP103: #N/A | BQ103: #N/A | BR103: #N/A | BS103: #N/A | BT103: #N/A | BU103: #N/A | BV103: #N/A | BW103: #N/A | BX103: #N/A | BY103: #N/A | BZ103: #N/A | CA103: #N/A | CB103: #N/A | CC103: #N/A | CD103: #N/A | CE103: #N/A | CF103: #N/A | CG103: #N/A | CH103: #N/A | CI103: #N/A | CJ103: #N/A | CK103: #N/A | CL103: #N/A | CM103: #N/A | CN103: #N/A | CO103: #N/A | CP103: #N/A | CQ103: #N/A | CR103: #N/A | CS103: #N/A | CT103: #N/A | CU103: #N/A | CV103: #N/A | CW103: #N/A

Sheet output
A3: Section | B3: n | C3: n0 | D3: n45 | E3: n135 | F3: n90 | G3: %0 | H3: %45 | I3: %90
A4: 1 | B4: =COUNT(transpose!B4:CW4) -> 28 | C4: =COUNTIF(transpose!B4:CW4,"=0") -> 10 | D4: =COUNTIF(transpose!B4:CW4,"=45") -> 6 | E4: =COUNTIF(transpose!B4:CW4,"=-45") -> 6 | F4: =COUNTIF(transpose!B4:CW4,"=90") -> 6 | G4: =C4/B4 -> 0.35714286 | H4: =(D4+E4)/B4 -> 0.42857143 | I4: =F4/B4 -> 0.21428571
A5: 2 | B5: =COUNT(transpose!B5:CW5) -> 11 | C5: =COUNTIF(transpose!B5:CW5,"=0") -> 1 | D5: =COUNTIF(transpose!B5:CW5,"=45") -> 4 | E5: =COUNTIF(transpose!B5:CW5,"=-45") -> 4 | F5: =COUNTIF(transpose!B5:CW5,"=90") -> 2 | G5: =C5/B5 -> 0.090909091 | H5: =(D5+E5)/B5 -> 0.72727273 | I5: =F5/B5 -> 0.18181818
A6: 3 | B6: =COUNT(transpose!B6:CW6) -> 11 | C6: =COUNTIF(transpose!B6:CW6,"=0") -> 5 | D6: =COUNTIF(transpose!B6:CW6,"=45") -> 2 | E6: =COUNTIF(transpose!B6:CW6,"=-45") -> 2 | F6: =COUNTIF(transpose!B6:CW6,"=90") -> 2 | G6: =C6/B6 -> 0.45454545 | H6: =(D6+E6)/B6 -> 0.36363636 | I6: =F6/B6 -> 0.18181818
A7: 4 | B7: =COUNT(transpose!B7:CW7) -> 0 | C7: =COUNTIF(transpose!B7:CW7,"=0") -> 0 | D7: =COUNTIF(transpose!B7:CW7,"=45") -> 0 | E7: =COUNTIF(transpose!B7:CW7,"=-45") -> 0 | F7: =COUNTIF(transpose!B7:CW7,"=90") -> 0 | G7: =C7/B7 -> #DIV/0! | H7: =(D7+E7)/B7 -> #DIV/0! | I7: =F7/B7 -> #DIV/0!
A8: 5 | B8: =COUNT(transpose!B8:CW8) -> 0 | C8: =COUNTIF(transpose!B8:CW8,"=0") -> 0 | D8: =COUNTIF(transpose!B8:CW8,"=45") -> 0 | E8: =COUNTIF(transpose!B8:CW8,"=-45") -> 0 | F8: =COUNTIF(transpose!B8:CW8,"=90") -> 0 | G8: =C8/B8 -> #DIV/0! | H8: =(D8+E8)/B8 -> #DIV/0! | I8: =F8/B8 -> #DIV/0!
A9: 6 | B9: =COUNT(transpose!B9:CW9) -> 0 | C9: =COUNTIF(transpose!B9:CW9,"=0") -> 0 | D9: =COUNTIF(transpose!B9:CW9,"=45") -> 0 | E9: =COUNTIF(transpose!B9:CW9,"=-45") -> 0 | F9: =COUNTIF(transpose!B9:CW9,"=90") -> 0 | G9: =C9/B9 -> #DIV/0! | H9: =(D9+E9)/B9 -> #DIV/0! | I9: =F9/B9 -> #DIV/0!
A10: 7 | B10: =COUNT(transpose!B10:CW10) -> 0 | C10: =COUNTIF(transpose!B10:CW10,"=0") -> 0 | D10: =COUNTIF(transpose!B10:CW10,"=45") -> 0 | E10: =COUNTIF(transpose!B10:CW10,"=-45") -> 0 | F10: =COUNTIF(transpose!B10:CW10,"=90") -> 0 | G10: =C10/B10 -> #DIV/0! | H10: =(D10+E10)/B10 -> #DIV/0! | I10: =F10/B10 -> #DIV/0!
A11: 8 | B11: =COUNT(transpose!B11:CW11) -> 0 | C11: =COUNTIF(transpose!B11:CW11,"=0") -> 0 | D11: =COUNTIF(transpose!B11:CW11,"=45") -> 0 | E11: =COUNTIF(transpose!B11:CW11,"=-45") -> 0 | F11: =COUNTIF(transpose!B11:CW11,"=90") -> 0 | G11: =C11/B11 -> #DIV/0! | H11: =(D11+E11)/B11 -> #DIV/0! | I11: =F11/B11 -> #DIV/0!
A12: 9 | B12: =COUNT(transpose!B12:CW12) -> 0 | C12: =COUNTIF(transpose!B12:CW12,"=0") -> 0 | D12: =COUNTIF(transpose!B12:CW12,"=45") -> 0 | E12: =COUNTIF(transpose!B12:CW12,"=-45") -> 0 | F12: =COUNTIF(transpose!B12:CW12,"=90") -> 0 | G12: =C12/B12 -> #DIV/0! | H12: =(D12+E12)/B12 -> #DIV/0! | I12: =F12/B12 -> #DIV/0!
A13: 10 | B13: =COUNT(transpose!B13:CW13) -> 0 | C13: =COUNTIF(transpose!B13:CW13,"=0") -> 0 | D13: =COUNTIF(transpose!B13:CW13,"=45") -> 0 | E13: =COUNTIF(transpose!B13:CW13,"=-45") -> 0 | F13: =COUNTIF(transpose!B13:CW13,"=90") -> 0 | G13: =C13/B13 -> #DIV/0! | H13: =(D13+E13)/B13 -> #DIV/0! | I13: =F13/B13 -> #DIV/0!
A14: 11 | B14: =COUNT(transpose!B14:CW14) -> 0 | C14: =COUNTIF(transpose!B14:CW14,"=0") -> 0 | D14: =COUNTIF(transpose!B14:CW14,"=45") -> 0 | E14: =COUNTIF(transpose!B14:CW14,"=-45") -> 0 | F14: =COUNTIF(transpose!B14:CW14,"=90") -> 0 | G14: =C14/B14 -> #DIV/0! | H14: =(D14+E14)/B14 -> #DIV/0! | I14: =F14/B14 -> #DIV/0!
A15: 12 | B15: =COUNT(transpose!B15:CW15) -> 0 | C15: =COUNTIF(transpose!B15:CW15,"=0") -> 0 | D15: =COUNTIF(transpose!B15:CW15,"=45") -> 0 | E15: =COUNTIF(transpose!B15:CW15,"=-45") -> 0 | F15: =COUNTIF(transpose!B15:CW15,"=90") -> 0 | G15: =C15/B15 -> #DIV/0! | H15: =(D15+E15)/B15 -> #DIV/0! | I15: =F15/B15 -> #DIV/0!
... A103: 100 | B103: =COUNT(transpose!B103:CW103) -> 0 | C103: =COUNTIF(transpose!B103:CW103,"=0") -> 0 | D103: =COUNTIF(transpose!B103:CW103,"=45") -> 0 | E103: =COUNTIF(transpose!B103:CW103,"=-45") -> 0 | F103: =COUNTIF(transpose!B103:CW103,"=90") -> 0 | G103: =C103/B103 -> #DIV/0! | H103: =(D103+E103)/B103 -> #DIV/0! | I103: =F103/B103 -> #DIV/0!
