Workbook
Name Nastran_Launcher: 'CONNECTORS'!$B$1
Name Nastran_Output_File: 'CONNECTORS'!$B$2
Name Output_File: 'CONNECTORS'!$B$2

Sheet VERSION_CONTROL
C3: VERSION | D3: AUTHOR | E3: DATE | F3: CHANGES
C4: 1.1.0 | D4: Enrique Maroto Herreros | E4: 46107 | F4: INITIAL RELEASE
C20: Cualquier bug o sugerencia contactar a través de email a:
C21: e.maroto.h@gmail.com

Sheet PILOT_POINTS
A1: PilotPoint_ID | B1: PilotPoint_Label | C1: X_ref | D1: Y_ref | E1: Z_ref | F1: Shank_definition_method | G1: X_shank | H1: Y_shank | I1: Z_shank | J1: Vector_definition_method | K1: X_vec | L1: Y_vec | M1: Z_vec
A2: 1 | B2: L01 | C2: 8044.8 | D2: -654.125 | E2: 2731.736 | F2: Vector | G2: 0 | H2: 1 | I2: 0 | J2: Vector | K2: 1 | L2: 0 | M2: 0
A3: 2 | B3: L02 | C3: 8044.8 | D3: -656.6 | E3: 2700.626 | F3: Vector | G3: 0 | H3: 1 | I3: 0 | J3: Vector | K3: 1 | L3: 0 | M3: 0
A4: 3 | B4: L03 | C4: 8044.8 | D4: -657.213 | E4: 2669.516 | F4: Vector | G4: 0 | H4: 1 | I4: 0 | J4: Vector | K4: 1 | L4: 0 | M4: 0
A5: 4 | B5: L04 | C5: 8044.8 | D5: -655.272 | E5: 2638.406 | F5: Vector | G5: 0 | H5: 1 | I5: 0 | J5: Vector | K5: 1 | L5: 0 | M5: 0
A6: 5 | B6: L05 | C6: 8044.8 | D6: -647.313 | E6: 2601.976 | F6: Vector | G6: 0 | H6: 1 | I6: 0 | J6: Vector | K6: 1 | L6: 0 | M6: 0
A7: 6 | B7: L06 | C7: 7994.8 | D7: -654.125 | E7: 2731.736 | F7: Vector | G7: 0 | H7: 1 | I7: 0 | J7: Vector | K7: 1 | L7: 0 | M7: 0
A8: 7 | B8: L07 | C8: 7994.8 | D8: -656.6 | E8: 2700.626 | F8: Vector | G8: 0 | H8: 1 | I8: 0 | J8: Vector | K8: 1 | L8: 0 | M8: 0
A9: 8 | B9: L08 | C9: 7994.8 | D9: -657.213 | E9: 2669.516 | F9: Vector | G9: 0 | H9: 1 | I9: 0 | J9: Vector | K9: 1 | L9: 0 | M9: 0
A10: 9 | B10: L09 | C10: 7994.8 | D10: -655.272 | E10: 2638.4 | F10: Vector | G10: 0 | H10: 1 | I10: 0 | J10: Vector | K10: 1 | L10: 0 | M10: 0
A11: 10 | B11: L10 | C11: 7994.8 | D11: -647.313 | E11: 2601.976 | F11: Vector | G11: 0 | H11: 1 | I11: 0 | J11: Vector | K11: 1 | L11: 0 | M11: 0
A12: 11 | B12: W01 | C12: 8022.3 | D12: -610.856 | E12: 2733.176 | F12: Vector | G12: 1 | H12: 0 | I12: 0 | J12: Vector | K12: 0 | L12: 1 | M12: 0
A13: 12 | B13: W02 | C13: 8022.3 | D13: -593.906 | E13: 2744.75 | F13: Vector | G13: 1 | H13: 0 | I13: 0 | J13: Vector | K13: 0 | L13: 1 | M13: 0
... A34: 33 | B34: F08 | C34: 7994.862 | D34: -553.54 | E34: 2767.95 | F34: Vector | G34: 0 | H34: 0 | I34: 1 | J34: Vector | K34: 0 | L34: 1 | M34: 0
A35: 34 | B35: FP-Fr-Rwd-01 | C35: 8031.8 | D35: -652.626 | E35: 2581.184 | F35: Vector | G35: 0 | H35: =-337.568-D35 -> 315.058 | I35: =2630.417-E35 -> 49.233 | J35: Vector | K35: 1 | L35: 0 | M35: 0
A36: 35 | B36: FP-Fr-Rwd-02 | C36: 8031.8 | D36: -646.886 | E36: 2555.7 | F36: Vector | G36: 0 | H36: =-337.568-D36 -> 309.318 | I36: =2630.417-E36 -> 74.717 | J36: Vector | K36: 1 | L36: 0 | M36: 0
A37: 36 | B37: FP-Fr-Rwd-03 | C37: 8031.8 | D37: -640.98 | E37: 2535.017 | F37: Vector | G37: 0 | H37: =-337.568-D37 -> 303.412 | I37: =2630.417-E37 -> 95.4 | J37: Vector | K37: 1 | L37: 0 | M37: 0
A38: 37 | B38: FP-Fr-Rwd-04 | C38: 8031.8 | D38: -633.919 | E38: 2514.717 | F38: Vector | G38: 0 | H38: =-337.568-D38 -> 296.351 | I38: =2630.417-E38 -> 115.7 | J38: Vector | K38: 1 | L38: 0 | M38: 0
A39: 38 | B39: FP-Fr-Rwd-05 | C39: 8031.8 | D39: -625.626 | E39: 2494.898 | F39: Vector | G39: 0 | H39: =-337.568-D39 -> 288.058 | I39: =2630.417-E39 -> 135.519 | J39: Vector | K39: 1 | L39: 0 | M39: 0
A40: 39 | B40: FP-Fr-Rwd-06 | C40: 8031.8 | D40: -616.04 | E40: 2475.7 | F40: Vector | G40: 0 | H40: =-337.568-D40 -> 278.472 | I40: =2630.417-E40 -> 154.717 | J40: Vector | K40: 1 | L40: 0 | M40: 0
A41: 40 | B41: FP-Fr-Rwd-07 | C41: 8031.8 | D41: -605.14 | E41: 2457.1 | F41: Vector | G41: 0 | H41: =-337.568-D41 -> 267.572 | I41: =2630.417-E41 -> 173.317 | J41: Vector | K41: 1 | L41: 0 | M41: 0
A42: 41 | B42: FP-Fr-Rwd-08 | C42: 8031.8 | D42: -591.92 | E42: 2439.5 | F42: Vector | G42: 0 | H42: =-337.568-D42 -> 254.352 | I42: =2630.417-E42 -> 190.917 | J42: Vector | K42: 1 | L42: 0 | M42: 0
A43: 42 | B43: FP-Fr-Rwd-09 | C43: 8031.8 | D43: -579.42 | E43: 2422.858 | F43: Vector | G43: 0 | H43: =-337.568-D43 -> 241.852 | I43: =2630.417-E43 -> 207.559 | J43: Vector | K43: 1 | L43: 0 | M43: 0
A44: 43 | B44: FP-Fr-Rwd-10 | C44: 8031.8 | D44: -564.72 | E44: 2407.22 | F44: Vector | G44: 0 | H44: =-337.568-D44 -> 227.152 | I44: =2630.417-E44 -> 223.197 | J44: Vector | K44: 1 | L44: 0 | M44: 0
A45: 44 | B45: FP-Fr-Rwd-11 | C45: 8031.8 | D45: -517.79 | E45: 2369 | F45: Vector | G45: 0 | H45: =-337.568-D45 -> 180.222 | I45: =2630.417-E45 -> 261.417 | J45: Vector | K45: 1 | L45: 0 | M45: 0
A46: 45 | B46: FP-Fr-Rwd-12 | C46: 8031.8 | D46: -498.32 | E46: 2357 | F46: Vector | G46: 0 | H46: =-337.568-D46 -> 160.752 | I46: =2630.417-E46 -> 273.417 | J46: Vector | K46: 1 | L46: 0 | M46: 0
... A52: 51 | B52: FP-Fr-Rwd-18 | C52: 8031.8 | D52: -361.459 | E52: 2304.229 | F52: Vector | G52: 0 | H52: =-337.568-D52 -> 23.891 | I52: =2630.417-E52 -> 326.188 | J52: Vector | K52: 1 | L52: 0 | M52: 0
A53: 52 | B53: FP-Fr-Fwd-01 | C53: 8008.8 | D53: =D35 -> -652.626 | E53: =E35 -> 2581.184 | F53: Vector | G53: 0 | H53: =-337.568-D53 -> 315.058 | I53: =2630.417-E53 -> 49.233 | J53: Vector | K53: 1 | L53: 0 | M53: 0
A54: 53 | B54: FP-Fr-Fwd-02 | C54: 8008.8 | D54: =D36 -> -646.886 | E54: =E36 -> 2555.7 | F54: Vector | G54: 0 | H54: =-337.568-D54 -> 309.318 | I54: =2630.417-E54 -> 74.717 | J54: Vector | K54: 1 | L54: 0 | M54: 0
A55: 54 | B55: FP-Fr-Fwd-03 | C55: 8008.8 | D55: =D37 -> -640.98 | E55: =E37 -> 2535.017 | F55: Vector | G55: 0 | H55: =-337.568-D55 -> 303.412 | I55: =2630.417-E55 -> 95.4 | J55: Vector | K55: 1 | L55: 0 | M55: 0
A56: 55 | B56: FP-Fr-Fwd-04 | C56: 8008.8 | D56: =D38 -> -633.919 | E56: =E38 -> 2514.717 | F56: Vector | G56: 0 | H56: =-337.568-D56 -> 296.351 | I56: =2630.417-E56 -> 115.7 | J56: Vector | K56: 1 | L56: 0 | M56: 0
A57: 56 | B57: FP-Fr-Fwd-05 | C57: 8008.8 | D57: =D39 -> -625.626 | E57: =E39 -> 2494.898 | F57: Vector | G57: 0 | H57: =-337.568-D57 -> 288.058 | I57: =2630.417-E57 -> 135.519 | J57: Vector | K57: 1 | L57: 0 | M57: 0
A58: 57 | B58: FP-Fr-Fwd-06 | C58: 8008.8 | D58: =D40 -> -616.04 | E58: =E40 -> 2475.7 | F58: Vector | G58: 0 | H58: =-337.568-D58 -> 278.472 | I58: =2630.417-E58 -> 154.717 | J58: Vector | K58: 1 | L58: 0 | M58: 0
A59: 58 | B59: FP-Fr-Fwd-07 | C59: 8008.8 | D59: =D41 -> -605.14 | E59: =E41 -> 2457.1 | F59: Vector | G59: 0 | H59: =-337.568-D59 -> 267.572 | I59: =2630.417-E59 -> 173.317 | J59: Vector | K59: 1 | L59: 0 | M59: 0
A60: 59 | B60: FP-Fr-Fwd-08 | C60: 8008.8 | D60: =D42 -> -591.92 | E60: =E42 -> 2439.5 | F60: Vector | G60: 0 | H60: =-337.568-D60 -> 254.352 | I60: =2630.417-E60 -> 190.917 | J60: Vector | K60: 1 | L60: 0 | M60: 0
A61: 60 | B61: FP-Fr-Fwd-09 | C61: 8008.8 | D61: =D43 -> -579.42 | E61: =E43 -> 2422.858 | F61: Vector | G61: 0 | H61: =-337.568-D61 -> 241.852 | I61: =2630.417-E61 -> 207.559 | J61: Vector | K61: 1 | L61: 0 | M61: 0
A62: 61 | B62: FP-Fr-Fwd-10 | C62: 8008.8 | D62: =D44 -> -564.72 | E62: =E44 -> 2407.22 | F62: Vector | G62: 0 | H62: =-337.568-D62 -> 227.152 | I62: =2630.417-E62 -> 223.197 | J62: Vector | K62: 1 | L62: 0 | M62: 0
A63: 62 | B63: FP-Fr-Fwd-11 | C63: 8008.8 | D63: =D45 -> -517.79 | E63: =E45 -> 2369 | F63: Vector | G63: 0 | H63: =-337.568-D63 -> 180.222 | I63: =2630.417-E63 -> 261.417 | J63: Vector | K63: 1 | L63: 0 | M63: 0
A64: 63 | B64: FP-Fr-Fwd-12 | C64: 8008.8 | D64: =D46 -> -498.32 | E64: =E46 -> 2357 | F64: Vector | G64: 0 | H64: =-337.568-D64 -> 160.752 | I64: =2630.417-E64 -> 273.417 | J64: Vector | K64: 1 | L64: 0 | M64: 0
... A70: 69 | B70: FP-Fr-Fwd-18 | C70: 8008.8 | D70: =D52 -> -361.459 | E70: =E52 -> 2304.229 | F70: Vector | G70: 0 | H70: =-337.568-D70 -> 23.891 | I70: =2630.417-E70 -> 326.188 | J70: Vector | K70: 1 | L70: 0 | M70: 0
...

Sheet FASTENERS
A1: Fastener_ID | B1: Fastener_Label | C1: E | D1: Diameter | E1: Head_Type | F1: Rivet
A2: 1 | B2: ABS2323K5 | C2: 110000 | D2: 4 | E2: PTR | F2: YES
A3: 2 | B3: NAS1790V | C3: 110000 | D3: 7.19 | E3: PTR | F3: YES
A4: 3 | B4: EN6115T4 | C4: 110000 | D4: 6.35 | E4: PTR | F4: YES
A5: 4 | B5: MS2047E6 | C5: 110000 | D5: 4 | E5: PTR | F5: YES
A6: 5 | B6: ABS0257-5 | C6: 110000 | D6: 4 | E6: CSK | F6: YES
A7: 6 | B7: ABS0257-8 | C7: 110000 | D7: 6.35 | E7: CSK | F7: YES
A8: 7 | B8: ABS2322K6 | C8: 110000 | D8: 4.8 | E8: CSK | F8: YES
A9: 8 | B9: EN6115T3 | C9: 110000 | D9: 4.8 | E9: PTR | F9: YES

Sheet CONNECTORS
A1: NASTRAN LAUNCHER | B1: C:\Users\U69432\Desktop\FWD-HF-DFEM-2D\FEM\FWD_HF_DFEM2D_v1.0.dat
A2: OUTPUT | B2: C:\Users\U69432\Desktop\FWD-HF-DFEM-2D\FEM\Fastener_test.bdf
A3: Create | B3: Connector_ID | C3: Connector_Label | D3: PilotPoint_Label | E3: Fastener_Label
A4: NO | B4: 1 | C4: =PILOT_POINTS!B2 -> L01 | D4: =CONNECTORS[[#This Row],[Connector_Label]] -> L01 | E4: ABS0257-8
A5: NO | B5: 2 | C5: =PILOT_POINTS!B3 -> L02 | D5: =CONNECTORS[[#This Row],[Connector_Label]] -> L02 | E5: ABS0257-8
A6: NO | B6: 3 | C6: =PILOT_POINTS!B4 -> L03 | D6: =CONNECTORS[[#This Row],[Connector_Label]] -> L03 | E6: ABS0257-8
A7: NO | B7: 4 | C7: =PILOT_POINTS!B5 -> L04 | D7: =CONNECTORS[[#This Row],[Connector_Label]] -> L04 | E7: ABS0257-8
A8: NO | B8: 5 | C8: =PILOT_POINTS!B6 -> L05 | D8: =CONNECTORS[[#This Row],[Connector_Label]] -> L05 | E8: ABS0257-8
A9: NO | B9: 6 | C9: =PILOT_POINTS!B7 -> L06 | D9: =CONNECTORS[[#This Row],[Connector_Label]] -> L06 | E9: ABS0257-8
A10: NO | B10: 7 | C10: =PILOT_POINTS!B8 -> L07 | D10: =CONNECTORS[[#This Row],[Connector_Label]] -> L07 | E10: ABS0257-8
A11: NO | B11: 8 | C11: =PILOT_POINTS!B9 -> L08 | D11: =CONNECTORS[[#This Row],[Connector_Label]] -> L08 | E11: ABS0257-8
A12: NO | B12: 9 | C12: =PILOT_POINTS!B10 -> L09 | D12: =CONNECTORS[[#This Row],[Connector_Label]] -> L09 | E12: ABS0257-8
A13: NO | B13: 10 | C13: =PILOT_POINTS!B11 -> L10 | D13: =CONNECTORS[[#This Row],[Connector_Label]] -> L10 | E13: ABS0257-8
A14: NO | B14: 11 | C14: =PILOT_POINTS!B12 -> W01 | D14: =CONNECTORS[[#This Row],[Connector_Label]] -> W01 | E14: EN6115T4
A15: NO | B15: 12 | C15: =PILOT_POINTS!B13 -> W02 | D15: =CONNECTORS[[#This Row],[Connector_Label]] -> W02 | E15: EN6115T4
... A113: NO | B113: 110 | C113: =PILOT_POINTS!B111 -> ANGL-FR-3 | D113: =CONNECTORS[[#This Row],[Connector_Label]] -> ANGL-FR-3 | E113: EN6115T3
